[I 160108 15:46:47 web:1908] 200 GET / (127.0.0.1) 191.00ms
[E 160108 15:46:48 web:1496] Uncaught exception GET / (127.0.0.1)
    HTTPServerRequest(protocol='http', host='127.0.0.1:15001', method='GET', uri='/', version='HTTP/1.1', remote_ip='127.0.0.1', headers={'Connection': 'keep-alive', 'Accept-Language': 'en-US,en;q=0.5', 'Accept-Encoding': 'gzip, deflate', 'Host': '127.0.0.1:15001', 'Accept': 'text/html,application/xhtml+xml,application/xml;q=0.9,*/*;q=0.8', 'User-Agent': 'Mozilla/5.0 (Windows NT 6.1; WOW64; rv:43.0) Gecko/20100101 Firefox/43.0'})
    Traceback (most recent call last):
      File "C:\Python27\lib\site-packages\tornado\web.py", line 1369, in _stack_context_handle_exception
        raise_exc_info((type, value, traceback))
      File "C:\Python27\lib\site-packages\tornado\stack_context.py", line 314, in wrapped
        ret = fn(*args, **kwargs)
      File "C:\Python27\lib\site-packages\tornado\gen.py", line 149, in final_callback
        if future.result() is not None:
      File "C:\Python27\lib\site-packages\tornado\concurrent.py", line 215, in result
        raise_exc_info(self._exc_info)
      File "C:\Python27\lib\site-packages\tornado\gen.py", line 215, in wrapper
        result = func(*args, **kwargs)
      File "E:/soheil/web_site_root/ieee/all_functions/tornado-get.py", line 945, in get
        self.finish()
      File "C:\Python27\lib\site-packages\tornado\web.py", line 905, in finish
        raise RuntimeError("finish() called twice")
    RuntimeError: finish() called twice
[W 160108 15:46:48 web:1908] 404 GET /favicon.ico (127.0.0.1) 6.00ms
[W 160108 15:46:48 web:1908] 404 GET /favicon.ico (127.0.0.1) 6.00ms
[I 160108 15:53:12 web:1908] 200 POST /index (127.0.0.1) 379084.00ms
[I 160527 18:44:07 web:1908] 200 GET / (127.0.0.1) 170.00ms
[E 160527 18:44:07 web:1496] Uncaught exception GET / (127.0.0.1)
    HTTPServerRequest(protocol='http', host='127.0.0.1:15001', method='GET', uri='/', version='HTTP/1.1', remote_ip='127.0.0.1', headers={'Connection': 'keep-alive', 'Accept-Language': 'en-US,en;q=0.5', 'Accept-Encoding': 'gzip, deflate', 'Host': '127.0.0.1:15001', 'Accept': 'text/html,application/xhtml+xml,application/xml;q=0.9,*/*;q=0.8', 'User-Agent': 'Mozilla/5.0 (Windows NT 6.1; WOW64; rv:46.0) Gecko/20100101 Firefox/46.0'})
    Traceback (most recent call last):
      File "C:\Python27\lib\site-packages\tornado\web.py", line 1369, in _stack_context_handle_exception
        raise_exc_info((type, value, traceback))
      File "C:\Python27\lib\site-packages\tornado\stack_context.py", line 314, in wrapped
        ret = fn(*args, **kwargs)
      File "C:\Python27\lib\site-packages\tornado\gen.py", line 149, in final_callback
        if future.result() is not None:
      File "C:\Python27\lib\site-packages\tornado\concurrent.py", line 215, in result
        raise_exc_info(self._exc_info)
      File "C:\Python27\lib\site-packages\tornado\gen.py", line 215, in wrapper
        result = func(*args, **kwargs)
      File "E:/soheil/web_site_root/ieee/all_functions/tornado-get.py", line 945, in get
        self.finish()
      File "C:\Python27\lib\site-packages\tornado\web.py", line 905, in finish
        raise RuntimeError("finish() called twice")
    RuntimeError: finish() called twice
[W 160527 18:44:07 web:1908] 404 GET /favicon.ico (127.0.0.1) 7.00ms
[W 160527 18:44:07 web:1908] 404 GET /favicon.ico (127.0.0.1) 5.00ms
[I 160527 18:51:09 web:1908] 200 POST /index (127.0.0.1) 384444.00ms
[W 160527 18:51:09 web:1908] 404 GET /htmls/simple_cursor.css (127.0.0.1) 10.00ms
[W 160527 18:51:09 web:1908] 404 GET /htmls/simple_cursor.css (127.0.0.1) 5.00ms
[E 160527 19:29:20 web:2584] Could not open static file 'E:\\soheil\\web_site_root\\ieee\\all_functions\\static\\1-s2.0-S009630031630282X-main.pdf'
[I 160527 19:29:20 web:1908] 200 POST /index (127.0.0.1) 1668360.00ms
[W 160527 19:29:20 web:1908] 404 GET /htmls/simple_cursor.css (127.0.0.1) 13.00ms
[I 160527 19:57:47 web:1908] 200 GET /index (127.0.0.1) 32.00ms
[E 160527 19:57:47 web:1496] Uncaught exception GET /index (127.0.0.1)
    HTTPServerRequest(protocol='http', host='127.0.0.1:15001', method='GET', uri='/index', version='HTTP/1.1', remote_ip='127.0.0.1', headers={'Connection': 'keep-alive', 'Accept-Language': 'en-US,en;q=0.5', 'Accept-Encoding': 'gzip, deflate', 'Host': '127.0.0.1:15001', 'Accept': 'text/html,application/xhtml+xml,application/xml;q=0.9,*/*;q=0.8', 'User-Agent': 'Mozilla/5.0 (Windows NT 6.1; WOW64; rv:46.0) Gecko/20100101 Firefox/46.0'})
    Traceback (most recent call last):
      File "C:\Python27\lib\site-packages\tornado\web.py", line 1369, in _stack_context_handle_exception
        raise_exc_info((type, value, traceback))
      File "C:\Python27\lib\site-packages\tornado\stack_context.py", line 314, in wrapped
        ret = fn(*args, **kwargs)
      File "C:\Python27\lib\site-packages\tornado\gen.py", line 149, in final_callback
        if future.result() is not None:
      File "C:\Python27\lib\site-packages\tornado\concurrent.py", line 215, in result
        raise_exc_info(self._exc_info)
      File "C:\Python27\lib\site-packages\tornado\gen.py", line 215, in wrapper
        result = func(*args, **kwargs)
      File "E:/soheil/web_site_root/ieee/all_functions/tornado-get.py", line 945, in get
        self.finish()
      File "C:\Python27\lib\site-packages\tornado\web.py", line 905, in finish
        raise RuntimeError("finish() called twice")
    RuntimeError: finish() called twice
[I 160527 20:00:11 web:1908] 200 POST /index (127.0.0.1) 57845.00ms
[W 160527 20:00:11 web:1908] 404 GET /htmls/simple_cursor.css (127.0.0.1) 11.00ms
[I 160527 20:00:13 web:1908] 200 GET /index (127.0.0.1) 22.00ms
[E 160527 20:00:13 web:1496] Uncaught exception GET /index (127.0.0.1)
    HTTPServerRequest(protocol='http', host='127.0.0.1:15001', method='GET', uri='/index', version='HTTP/1.1', remote_ip='127.0.0.1', headers={'Connection': 'keep-alive', 'Accept-Language': 'en-US,en;q=0.5', 'Accept-Encoding': 'gzip, deflate', 'Host': '127.0.0.1:15001', 'Accept': 'text/html,application/xhtml+xml,application/xml;q=0.9,*/*;q=0.8', 'User-Agent': 'Mozilla/5.0 (Windows NT 6.1; WOW64; rv:46.0) Gecko/20100101 Firefox/46.0'})
    Traceback (most recent call last):
      File "C:\Python27\lib\site-packages\tornado\web.py", line 1369, in _stack_context_handle_exception
        raise_exc_info((type, value, traceback))
      File "C:\Python27\lib\site-packages\tornado\stack_context.py", line 314, in wrapped
        ret = fn(*args, **kwargs)
      File "C:\Python27\lib\site-packages\tornado\gen.py", line 149, in final_callback
        if future.result() is not None:
      File "C:\Python27\lib\site-packages\tornado\concurrent.py", line 215, in result
        raise_exc_info(self._exc_info)
      File "C:\Python27\lib\site-packages\tornado\gen.py", line 215, in wrapper
        result = func(*args, **kwargs)
      File "E:/soheil/web_site_root/ieee/all_functions/tornado-get.py", line 945, in get
        self.finish()
      File "C:\Python27\lib\site-packages\tornado\web.py", line 905, in finish
        raise RuntimeError("finish() called twice")
    RuntimeError: finish() called twice
[I 160527 20:13:50 web:1908] 200 POST /index (127.0.0.1) 353807.00ms
[W 160527 20:13:50 web:1908] 404 GET /htmls/simple_cursor.css (127.0.0.1) 15.00ms
[I 160527 20:13:56 autoreload:204] E:/soheil/web_site_root/ieee/all_functions/configs/Links_site/www_sciencedirect_com.py modified; restarting server
[I 160527 20:29:58 web:1908] 200 GET /index (127.0.0.1) 65.00ms
[E 160527 20:29:58 web:1496] Uncaught exception GET /index (127.0.0.1)
    HTTPServerRequest(protocol='http', host='127.0.0.1:15001', method='GET', uri='/index', version='HTTP/1.1', remote_ip='127.0.0.1', headers={'Connection': 'keep-alive', 'Accept-Language': 'en-US,en;q=0.5', 'Accept-Encoding': 'gzip, deflate', 'Host': '127.0.0.1:15001', 'Accept': 'text/html,application/xhtml+xml,application/xml;q=0.9,*/*;q=0.8', 'User-Agent': 'Mozilla/5.0 (Windows NT 6.1; WOW64; rv:46.0) Gecko/20100101 Firefox/46.0'})
    Traceback (most recent call last):
      File "C:\Python27\lib\site-packages\tornado\web.py", line 1369, in _stack_context_handle_exception
        raise_exc_info((type, value, traceback))
      File "C:\Python27\lib\site-packages\tornado\stack_context.py", line 314, in wrapped
        ret = fn(*args, **kwargs)
      File "C:\Python27\lib\site-packages\tornado\gen.py", line 149, in final_callback
        if future.result() is not None:
      File "C:\Python27\lib\site-packages\tornado\concurrent.py", line 215, in result
        raise_exc_info(self._exc_info)
      File "C:\Python27\lib\site-packages\tornado\gen.py", line 215, in wrapper
        result = func(*args, **kwargs)
      File "E:/soheil/web_site_root/ieee/all_functions/tornado-get.py", line 945, in get
        self.finish()
      File "C:\Python27\lib\site-packages\tornado\web.py", line 905, in finish
        raise RuntimeError("finish() called twice")
    RuntimeError: finish() called twice
[E 160527 21:39:34 web:2584] Could not open static file 'E:\\soheil\\web_site_root\\ieee\\all_functions\\static\\1-s2.0-S0142061516303647-main.pdf'
[I 160527 21:39:34 web:1908] 200 POST /index (127.0.0.1) 183988.00ms
[W 160527 21:39:34 web:1908] 404 GET /htmls/simple_cursor.css (127.0.0.1) 23.00ms
[I 160527 23:08:29 web:1908] 200 GET /index (127.0.0.1) 855.00ms
[E 160527 23:08:30 web:1496] Uncaught exception GET /index (127.0.0.1)
    HTTPServerRequest(protocol='http', host='127.0.0.1:15001', method='GET', uri='/index', version='HTTP/1.1', remote_ip='127.0.0.1', headers={'Connection': 'keep-alive', 'Accept-Language': 'en-US,en;q=0.5', 'Accept-Encoding': 'gzip, deflate', 'Host': '127.0.0.1:15001', 'Accept': 'text/html,application/xhtml+xml,application/xml;q=0.9,*/*;q=0.8', 'User-Agent': 'Mozilla/5.0 (Windows NT 6.1; WOW64; rv:46.0) Gecko/20100101 Firefox/46.0'})
    Traceback (most recent call last):
      File "C:\Python27\lib\site-packages\tornado\web.py", line 1369, in _stack_context_handle_exception
        raise_exc_info((type, value, traceback))
      File "C:\Python27\lib\site-packages\tornado\stack_context.py", line 314, in wrapped
        ret = fn(*args, **kwargs)
      File "C:\Python27\lib\site-packages\tornado\gen.py", line 149, in final_callback
        if future.result() is not None:
      File "C:\Python27\lib\site-packages\tornado\concurrent.py", line 215, in result
        raise_exc_info(self._exc_info)
      File "C:\Python27\lib\site-packages\tornado\gen.py", line 215, in wrapper
        result = func(*args, **kwargs)
      File "E:/soheil/web_site_root/ieee/all_functions/tornado-get.py", line 945, in get
        self.finish()
      File "C:\Python27\lib\site-packages\tornado\web.py", line 905, in finish
        raise RuntimeError("finish() called twice")
    RuntimeError: finish() called twice
[I 160527 23:28:01 web:1908] 304 GET / (127.0.0.1) 53.00ms
[E 160527 23:28:01 web:1496] Uncaught exception GET / (127.0.0.1)
    HTTPServerRequest(protocol='http', host='127.0.0.1:15001', method='GET', uri='/', version='HTTP/1.1', remote_ip='127.0.0.1', headers={'Connection': 'keep-alive', 'Accept-Language': 'en-US,en;q=0.5', 'Accept-Encoding': 'gzip, deflate', 'If-None-Match': '"6e39e81c6d5a5f4e0ea711e7222945ee62e8549f"', 'Host': '127.0.0.1:15001', 'Accept': 'text/html,application/xhtml+xml,application/xml;q=0.9,*/*;q=0.8', 'User-Agent': 'Mozilla/5.0 (Windows NT 6.1; WOW64; rv:46.0) Gecko/20100101 Firefox/46.0'})
    Traceback (most recent call last):
      File "C:\Python27\lib\site-packages\tornado\web.py", line 1369, in _stack_context_handle_exception
        raise_exc_info((type, value, traceback))
      File "C:\Python27\lib\site-packages\tornado\stack_context.py", line 314, in wrapped
        ret = fn(*args, **kwargs)
      File "C:\Python27\lib\site-packages\tornado\gen.py", line 149, in final_callback
        if future.result() is not None:
      File "C:\Python27\lib\site-packages\tornado\concurrent.py", line 215, in result
        raise_exc_info(self._exc_info)
      File "C:\Python27\lib\site-packages\tornado\gen.py", line 215, in wrapper
        result = func(*args, **kwargs)
      File "E:/soheil/web_site_root/ieee/all_functions/tornado-get.py", line 945, in get
        self.finish()
      File "C:\Python27\lib\site-packages\tornado\web.py", line 905, in finish
        raise RuntimeError("finish() called twice")
    RuntimeError: finish() called twice
[W 160527 23:28:02 web:1908] 404 GET /favicon.ico (127.0.0.1) 13.00ms
[W 160527 23:28:02 web:1908] 404 GET /favicon.ico (127.0.0.1) 9.00ms
[I 160527 23:28:05 web:1908] 200 GET / (127.0.0.1) 15.00ms
[E 160527 23:28:05 web:1496] Uncaught exception GET / (127.0.0.1)
    HTTPServerRequest(protocol='http', host='127.0.0.1:15001', method='GET', uri='/', version='HTTP/1.1', remote_ip='127.0.0.1', headers={'Accept-Language': 'en-US,en;q=0.5', 'Accept-Encoding': 'gzip, deflate', 'Host': '127.0.0.1:15001', 'Accept': 'text/html,application/xhtml+xml,application/xml;q=0.9,*/*;q=0.8', 'User-Agent': 'Mozilla/5.0 (Windows NT 6.1; WOW64; rv:46.0) Gecko/20100101 Firefox/46.0', 'Connection': 'keep-alive', 'Pragma': 'no-cache', 'Cache-Control': 'no-cache'})
    Traceback (most recent call last):
      File "C:\Python27\lib\site-packages\tornado\web.py", line 1369, in _stack_context_handle_exception
        raise_exc_info((type, value, traceback))
      File "C:\Python27\lib\site-packages\tornado\stack_context.py", line 314, in wrapped
        ret = fn(*args, **kwargs)
      File "C:\Python27\lib\site-packages\tornado\gen.py", line 149, in final_callback
        if future.result() is not None:
      File "C:\Python27\lib\site-packages\tornado\concurrent.py", line 215, in result
        raise_exc_info(self._exc_info)
      File "C:\Python27\lib\site-packages\tornado\gen.py", line 215, in wrapper
        result = func(*args, **kwargs)
      File "E:/soheil/web_site_root/ieee/all_functions/tornado-get.py", line 945, in get
        self.finish()
      File "C:\Python27\lib\site-packages\tornado\web.py", line 905, in finish
        raise RuntimeError("finish() called twice")
    RuntimeError: finish() called twice
[I 160527 23:39:38 web:1908] 200 POST /index (127.0.0.1) 198107.00ms
[W 160527 23:39:38 web:1908] 404 GET /htmls/simple_cursor.css (127.0.0.1) 16.00ms
[I 160527 23:39:39 autoreload:204] E:/soheil/web_site_root/ieee/all_functions/configs/Links_site/www_sciencedirect_com.py modified; restarting server
[I 160527 23:57:12 web:1908] 200 POST /index (127.0.0.1) 185791.00ms
[W 160527 23:57:12 web:1908] 404 GET /htmls/simple_cursor.css (127.0.0.1) 15.00ms
[I 160528 10:00:42 web:1908] 200 POST /index (127.0.0.1) 33037898.00ms
[E 160528 10:01:30 concurrent:124] Future exception was never retrieved: Traceback (most recent call last):
      File "C:\Python27\lib\site-packages\tornado\gen.py", line 505, in Task
        func(*args, callback=_argument_adapter(set_result), **kwargs)
    TypeError: 'dict' object is not callable
[E 160528 11:04:51 web:1496] Uncaught exception POST /index (127.0.0.1)
    HTTPServerRequest(protocol='http', host='127.0.0.1:15001', method='POST', uri='/index', version='HTTP/1.1', remote_ip='127.0.0.1', headers={'Content-Length': '167', 'Accept-Language': 'en-US,en;q=0.5', 'Accept-Encoding': 'gzip, deflate', 'Host': '127.0.0.1:15001', 'Accept': 'text/html,application/xhtml+xml,application/xml;q=0.9,*/*;q=0.8', 'User-Agent': 'Mozilla/5.0 (Windows NT 6.1; WOW64; rv:46.0) Gecko/20100101 Firefox/46.0', 'Connection': 'keep-alive', 'Referer': 'http://127.0.0.1:15001/', 'Content-Type': 'application/x-www-form-urlencoded'})
    Traceback (most recent call last):
      File "C:\Python27\lib\site-packages\tornado\web.py", line 1369, in _stack_context_handle_exception
        raise_exc_info((type, value, traceback))
      File "C:\Python27\lib\site-packages\tornado\stack_context.py", line 314, in wrapped
        ret = fn(*args, **kwargs)
      File "C:\Python27\lib\site-packages\tornado\gen.py", line 149, in final_callback
        if future.result() is not None:
      File "C:\Python27\lib\site-packages\tornado\concurrent.py", line 215, in result
        raise_exc_info(self._exc_info)
      File "C:\Python27\lib\site-packages\tornado\gen.py", line 215, in wrapper
        result = func(*args, **kwargs)
      File "E:/soheil/web_site_root/ieee/all_functions/tornado-get.py", line 521, in post
        result = tornado.gen.Task(self.download(details))
      File "E:/soheil/web_site_root/ieee/all_functions/tornado-get.py", line 592, in download
        water_pdfdir=root+water_pdfdir,)
      File "E:/soheil/web_site_root/ieee/all_functions\main_core.py", line 169, in valid_link
        responce= self.Find_Link(self.url,pdfdir=pdf_download_location,water_pdfdir=wat_locatton,cookies=cookies).find_link(self.pr,self.us_pss)
      File "E:/soheil/web_site_root/ieee/all_functions\find_link.py", line 262, in find_link
        res = self.new_module.LINK(url).get_pdf_link(proxy, user_pass)
      File "E:/soheil/web_site_root/ieee/all_functions/configs/Links_site/www_sciencedirect_com.py", line 3071, in get_pdf_link
        [html, cookies, links, title, form, time_diff, log_out] = twil_find_pdf_link(url)
      File "E:/soheil/web_site_root/ieee/all_functions/configs/Links_site/www_sciencedirect_com.py", line 1264, in twil_find_pdf_link
        if links != []:
    UnboundLocalError: local variable 'links' referenced before assignment
[E 160528 11:04:51 web:1908] 500 POST /index (127.0.0.1) 977.00ms
[E 160528 11:05:02 web:1496] Uncaught exception POST /index (127.0.0.1)
    HTTPServerRequest(protocol='http', host='127.0.0.1:15001', method='POST', uri='/index', version='HTTP/1.1', remote_ip='127.0.0.1', headers={'Content-Length': '167', 'Accept-Language': 'en-US,en;q=0.5', 'Accept-Encoding': 'gzip, deflate', 'Host': '127.0.0.1:15001', 'Accept': 'text/html,application/xhtml+xml,application/xml;q=0.9,*/*;q=0.8', 'User-Agent': 'Mozilla/5.0 (Windows NT 6.1; WOW64; rv:46.0) Gecko/20100101 Firefox/46.0', 'Connection': 'keep-alive', 'Referer': 'http://127.0.0.1:15001/', 'Content-Type': 'application/x-www-form-urlencoded'})
    Traceback (most recent call last):
      File "C:\Python27\lib\site-packages\tornado\web.py", line 1369, in _stack_context_handle_exception
        raise_exc_info((type, value, traceback))
      File "C:\Python27\lib\site-packages\tornado\stack_context.py", line 314, in wrapped
        ret = fn(*args, **kwargs)
      File "C:\Python27\lib\site-packages\tornado\gen.py", line 149, in final_callback
        if future.result() is not None:
      File "C:\Python27\lib\site-packages\tornado\concurrent.py", line 215, in result
        raise_exc_info(self._exc_info)
      File "C:\Python27\lib\site-packages\tornado\gen.py", line 215, in wrapper
        result = func(*args, **kwargs)
      File "E:/soheil/web_site_root/ieee/all_functions/tornado-get.py", line 521, in post
        result = tornado.gen.Task(self.download(details))
      File "E:/soheil/web_site_root/ieee/all_functions/tornado-get.py", line 592, in download
        water_pdfdir=root+water_pdfdir,)
      File "E:/soheil/web_site_root/ieee/all_functions\main_core.py", line 169, in valid_link
        responce= self.Find_Link(self.url,pdfdir=pdf_download_location,water_pdfdir=wat_locatton,cookies=cookies).find_link(self.pr,self.us_pss)
      File "E:/soheil/web_site_root/ieee/all_functions\find_link.py", line 262, in find_link
        res = self.new_module.LINK(url).get_pdf_link(proxy, user_pass)
      File "E:/soheil/web_site_root/ieee/all_functions/configs/Links_site/www_sciencedirect_com.py", line 3071, in get_pdf_link
        [html, cookies, links, title, form, time_diff, log_out] = twil_find_pdf_link(url)
      File "E:/soheil/web_site_root/ieee/all_functions/configs/Links_site/www_sciencedirect_com.py", line 1264, in twil_find_pdf_link
        if links != []:
    UnboundLocalError: local variable 'links' referenced before assignment
[E 160528 11:05:02 web:1908] 500 POST /index (127.0.0.1) 57.00ms
[E 160528 11:05:13 web:1496] Uncaught exception POST /index (127.0.0.1)
    HTTPServerRequest(protocol='http', host='127.0.0.1:15001', method='POST', uri='/index', version='HTTP/1.1', remote_ip='127.0.0.1', headers={'Content-Length': '167', 'Accept-Language': 'en-US,en;q=0.5', 'Accept-Encoding': 'gzip, deflate', 'Host': '127.0.0.1:15001', 'Accept': 'text/html,application/xhtml+xml,application/xml;q=0.9,*/*;q=0.8', 'User-Agent': 'Mozilla/5.0 (Windows NT 6.1; WOW64; rv:46.0) Gecko/20100101 Firefox/46.0', 'Connection': 'keep-alive', 'Referer': 'http://127.0.0.1:15001/', 'Content-Type': 'application/x-www-form-urlencoded'})
    Traceback (most recent call last):
      File "C:\Python27\lib\site-packages\tornado\web.py", line 1369, in _stack_context_handle_exception
        raise_exc_info((type, value, traceback))
      File "C:\Python27\lib\site-packages\tornado\stack_context.py", line 314, in wrapped
        ret = fn(*args, **kwargs)
      File "C:\Python27\lib\site-packages\tornado\gen.py", line 149, in final_callback
        if future.result() is not None:
      File "C:\Python27\lib\site-packages\tornado\concurrent.py", line 215, in result
        raise_exc_info(self._exc_info)
      File "C:\Python27\lib\site-packages\tornado\gen.py", line 215, in wrapper
        result = func(*args, **kwargs)
      File "E:/soheil/web_site_root/ieee/all_functions/tornado-get.py", line 521, in post
        result = tornado.gen.Task(self.download(details))
      File "E:/soheil/web_site_root/ieee/all_functions/tornado-get.py", line 592, in download
        water_pdfdir=root+water_pdfdir,)
      File "E:/soheil/web_site_root/ieee/all_functions\main_core.py", line 169, in valid_link
        responce= self.Find_Link(self.url,pdfdir=pdf_download_location,water_pdfdir=wat_locatton,cookies=cookies).find_link(self.pr,self.us_pss)
      File "E:/soheil/web_site_root/ieee/all_functions\find_link.py", line 262, in find_link
        res = self.new_module.LINK(url).get_pdf_link(proxy, user_pass)
      File "E:/soheil/web_site_root/ieee/all_functions/configs/Links_site/www_sciencedirect_com.py", line 3071, in get_pdf_link
        [html, cookies, links, title, form, time_diff, log_out] = twil_find_pdf_link(url)
      File "E:/soheil/web_site_root/ieee/all_functions/configs/Links_site/www_sciencedirect_com.py", line 1264, in twil_find_pdf_link
        if links != []:
    UnboundLocalError: local variable 'links' referenced before assignment
[E 160528 11:05:13 web:1908] 500 POST /index (127.0.0.1) 789.00ms
[E 160528 11:05:45 web:1496] Uncaught exception POST /index (127.0.0.1)
    HTTPServerRequest(protocol='http', host='127.0.0.1:15001', method='POST', uri='/index', version='HTTP/1.1', remote_ip='127.0.0.1', headers={'Content-Length': '167', 'Accept-Language': 'en-US,en;q=0.5', 'Accept-Encoding': 'gzip, deflate', 'Host': '127.0.0.1:15001', 'Accept': 'text/html,application/xhtml+xml,application/xml;q=0.9,*/*;q=0.8', 'User-Agent': 'Mozilla/5.0 (Windows NT 6.1; WOW64; rv:46.0) Gecko/20100101 Firefox/46.0', 'Connection': 'keep-alive', 'Referer': 'http://127.0.0.1:15001/', 'Content-Type': 'application/x-www-form-urlencoded'})
    Traceback (most recent call last):
      File "C:\Python27\lib\site-packages\tornado\web.py", line 1369, in _stack_context_handle_exception
        raise_exc_info((type, value, traceback))
      File "C:\Python27\lib\site-packages\tornado\stack_context.py", line 314, in wrapped
        ret = fn(*args, **kwargs)
      File "C:\Python27\lib\site-packages\tornado\gen.py", line 149, in final_callback
        if future.result() is not None:
      File "C:\Python27\lib\site-packages\tornado\concurrent.py", line 215, in result
        raise_exc_info(self._exc_info)
      File "C:\Python27\lib\site-packages\tornado\gen.py", line 215, in wrapper
        result = func(*args, **kwargs)
      File "E:/soheil/web_site_root/ieee/all_functions/tornado-get.py", line 521, in post
        result = tornado.gen.Task(self.download(details))
      File "E:/soheil/web_site_root/ieee/all_functions/tornado-get.py", line 592, in download
        water_pdfdir=root+water_pdfdir,)
      File "E:/soheil/web_site_root/ieee/all_functions\main_core.py", line 169, in valid_link
        responce= self.Find_Link(self.url,pdfdir=pdf_download_location,water_pdfdir=wat_locatton,cookies=cookies).find_link(self.pr,self.us_pss)
      File "E:/soheil/web_site_root/ieee/all_functions\find_link.py", line 262, in find_link
        res = self.new_module.LINK(url).get_pdf_link(proxy, user_pass)
      File "E:/soheil/web_site_root/ieee/all_functions/configs/Links_site/www_sciencedirect_com.py", line 3070, in get_pdf_link
        [html, cookies, links, title, form, time_diff, log_out] = twil_find_pdf_link(url)
      File "E:/soheil/web_site_root/ieee/all_functions/configs/Links_site/www_sciencedirect_com.py", line 1264, in twil_find_pdf_link
        if links != []:
    UnboundLocalError: local variable 'links' referenced before assignment
[E 160528 11:05:45 web:1908] 500 POST /index (127.0.0.1) 921.00ms
[E 160528 19:50:25 web:1496] Uncaught exception POST /index (127.0.0.1)
    HTTPServerRequest(protocol='http', host='127.0.0.1:15001', method='POST', uri='/index', version='HTTP/1.1', remote_ip='127.0.0.1', headers={'Content-Length': '167', 'Accept-Language': 'en-US,en;q=0.5', 'Accept-Encoding': 'gzip, deflate', 'Host': '127.0.0.1:15001', 'Accept': 'text/html,application/xhtml+xml,application/xml;q=0.9,*/*;q=0.8', 'User-Agent': 'Mozilla/5.0 (Windows NT 6.1; WOW64; rv:46.0) Gecko/20100101 Firefox/46.0', 'Connection': 'keep-alive', 'Referer': 'http://127.0.0.1:15001/', 'Content-Type': 'application/x-www-form-urlencoded'})
    Traceback (most recent call last):
      File "C:\Python27\lib\site-packages\tornado\web.py", line 1369, in _stack_context_handle_exception
        raise_exc_info((type, value, traceback))
      File "C:\Python27\lib\site-packages\tornado\stack_context.py", line 314, in wrapped
        ret = fn(*args, **kwargs)
      File "C:\Python27\lib\site-packages\tornado\gen.py", line 149, in final_callback
        if future.result() is not None:
      File "C:\Python27\lib\site-packages\tornado\concurrent.py", line 215, in result
        raise_exc_info(self._exc_info)
      File "C:\Python27\lib\site-packages\tornado\gen.py", line 215, in wrapper
        result = func(*args, **kwargs)
      File "E:/soheil/web_site_root/ieee/all_functions/tornado-get.py", line 521, in post
        result = tornado.gen.Task(self.download(details))
      File "E:/soheil/web_site_root/ieee/all_functions/tornado-get.py", line 592, in download
        water_pdfdir=root+water_pdfdir,)
      File "E:/soheil/web_site_root/ieee/all_functions\main_core.py", line 169, in valid_link
        responce= self.Find_Link(self.url,pdfdir=pdf_download_location,water_pdfdir=wat_locatton,cookies=cookies).find_link(self.pr,self.us_pss)
      File "E:/soheil/web_site_root/ieee/all_functions\find_link.py", line 133, in __init__
        self.new_module = __import__(site.replace('.', '_'), {}, {}, [], 2)
      File "E:/soheil/web_site_root/ieee/all_functions/configs/Links_site/www_sciencedirect_com.py", line 2544
        if links == '' or links == [] or links == None:
        ^
    IndentationError: expected an indented block
[E 160528 19:50:25 web:1908] 500 POST /index (127.0.0.1) 1083.00ms
[I 160528 19:53:54 web:1908] 200 POST /index (127.0.0.1) 191551.00ms
[W 160528 19:53:54 web:1908] 404 GET /htmls/simple_cursor.css (127.0.0.1) 12.00ms
[I 160528 20:02:56 web:1908] 200 POST /index (127.0.0.1) 218569.00ms
[W 160528 20:02:59 web:1908] 404 GET /htmls/simple_cursor.css (127.0.0.1) 597.00ms
[E 160528 21:03:16 web:1496] Uncaught exception POST /index (127.0.0.1)
    HTTPServerRequest(protocol='http', host='127.0.0.1:15001', method='POST', uri='/index', version='HTTP/1.1', remote_ip='127.0.0.1', headers={'Content-Length': '167', 'Accept-Language': 'en-US,en;q=0.5', 'Accept-Encoding': 'gzip, deflate', 'Host': '127.0.0.1:15001', 'Accept': 'text/html,application/xhtml+xml,application/xml;q=0.9,*/*;q=0.8', 'User-Agent': 'Mozilla/5.0 (Windows NT 6.1; WOW64; rv:46.0) Gecko/20100101 Firefox/46.0', 'Connection': 'keep-alive', 'Referer': 'http://127.0.0.1:15001/', 'Content-Type': 'application/x-www-form-urlencoded'})
    Traceback (most recent call last):
      File "C:\Python27\lib\site-packages\tornado\web.py", line 1369, in _stack_context_handle_exception
        raise_exc_info((type, value, traceback))
      File "C:\Python27\lib\site-packages\tornado\stack_context.py", line 314, in wrapped
        ret = fn(*args, **kwargs)
      File "C:\Python27\lib\site-packages\tornado\gen.py", line 149, in final_callback
        if future.result() is not None:
      File "C:\Python27\lib\site-packages\tornado\concurrent.py", line 215, in result
        raise_exc_info(self._exc_info)
      File "C:\Python27\lib\site-packages\tornado\gen.py", line 215, in wrapper
        result = func(*args, **kwargs)
      File "E:/soheil/web_site_root/ieee/all_functions/tornado-get.py", line 521, in post
        result = tornado.gen.Task(self.download(details))
      File "E:/soheil/web_site_root/ieee/all_functions/tornado-get.py", line 592, in download
        water_pdfdir=root+water_pdfdir,)
      File "E:/soheil/web_site_root/ieee/all_functions\main_core.py", line 169, in valid_link
        responce= self.Find_Link(self.url,pdfdir=pdf_download_location,water_pdfdir=wat_locatton,cookies=cookies).find_link(self.pr,self.us_pss)
      File "E:/soheil/web_site_root/ieee/all_functions\find_link.py", line 262, in find_link
        res = self.new_module.LINK(url).get_pdf_link(proxy, user_pass)
      File "E:/soheil/web_site_root/ieee/all_functions/configs/Links_site/www_sciencedirect_com.py", line 3136, in get_pdf_link
        [html, cookies, links, title, form, time_diff, log_out] = twil_find_pdf_link(url)
      File "E:/soheil/web_site_root/ieee/all_functions/configs/Links_site/www_sciencedirect_com.py", line 1260, in twil_find_pdf_link
        [html, cookies, links, title, times, log_out] = tw.twill_find_link(link, form[k])
      File "E:/soheil/web_site_root/ieee/all_functions/configs/Links_site/www_sciencedirect_com.py", line 2395, in twill_find_link
        t_brw.follow_link(t2)
      File "C:\Python27\lib\site-packages\twill-0.9.1-py2.7.egg\twill\browser.py", line 207, in follow_link
        self._journey('follow_link', link)
      File "C:\Python27\lib\site-packages\twill-0.9.1-py2.7.egg\twill\browser.py", line 523, in _journey
        r = func(*args, **kwargs)
      File "C:\Python27\lib\site-packages\twill-0.9.1-py2.7.egg\twill\other_packages\_mechanize_dist\_mechanize.py", line 577, in follow_link
        return self.open(self.click_link(link, **kwds))
      File "C:\Python27\lib\site-packages\twill-0.9.1-py2.7.egg\twill\other_packages\_mechanize_dist\_mechanize.py", line 212, in open
        return self._mech_open(url, data)
      File "C:\Python27\lib\site-packages\twill-0.9.1-py2.7.egg\twill\other_packages\_mechanize_dist\_mechanize.py", line 257, in _mech_open
        self._set_response(response, False)
      File "C:\Python27\lib\site-packages\twill-0.9.1-py2.7.egg\twill\other_packages\_mechanize_dist\_mechanize.py", line 316, in _set_response
        self._factory.set_response(response)
      File "C:\Python27\lib\site-packages\twill-0.9.1-py2.7.egg\twill\utils.py", line 325, in set_response
        self.factory.set_response(cleaned_response)
      File "C:\Python27\lib\site-packages\twill-0.9.1-py2.7.egg\twill\other_packages\_mechanize_dist\_html.py", line 602, in set_response
        soup = self._soup_class(self.encoding, data)
      File "C:\Python27\lib\site-packages\twill-0.9.1-py2.7.egg\twill\other_packages\_mechanize_dist\_html.py", line 314, in __init__
        self, text, avoidParserProblems, initialTextIsEverything)
      File "C:\Python27\lib\site-packages\twill-0.9.1-py2.7.egg\twill\other_packages\_mechanize_dist\_beautifulsoup.py", line 674, in __init__
        self.feed(text)
      File "C:\Python27\lib\site-packages\twill-0.9.1-py2.7.egg\twill\other_packages\_mechanize_dist\_beautifulsoup.py", line 693, in feed
        SGMLParser.feed(self, text)
      File "C:\Python27\lib\sgmllib.py", line 104, in feed
        self.goahead(0)
      File "C:\Python27\lib\sgmllib.py", line 186, in goahead
        self.handle_charref(name)
      File "C:\Python27\lib\site-packages\twill-0.9.1-py2.7.egg\twill\other_packages\_mechanize_dist\_html.py", line 317, in handle_charref
        t = unescape("&#%s;"%ref, self._entitydefs, self._encoding)
      File "C:\Python27\lib\site-packages\twill-0.9.1-py2.7.egg\twill\other_packages\_mechanize_dist\_html.py", line 274, in unescape
        return re.sub(r"&#?[A-Za-z0-9]+?;", replace_entities, data)
      File "C:\Python27\lib\re.py", line 155, in sub
        return _compile(pattern, flags).sub(repl, string, count)
      File "C:\Python27\lib\site-packages\twill-0.9.1-py2.7.egg\twill\other_packages\_mechanize_dist\_html.py", line 260, in replace_entities
        return unescape_charref(ent[2:-1], encoding)
      File "C:\Python27\lib\site-packages\twill-0.9.1-py2.7.egg\twill\other_packages\_mechanize_dist\_html.py", line 280, in unescape_charref
        uc = unichr(int(name, base))
    ValueError: invalid literal for int() with base 10: 'd'
[E 160528 21:03:16 web:1908] 500 POST /index (127.0.0.1) 91070.00ms
[I 160528 21:03:23 autoreload:204] E:/soheil/web_site_root/ieee/all_functions/configs/Links_site/www_sciencedirect_com.py modified; restarting server
[I 160528 21:16:38 autoreload:204] C:\Python27\lib\urllib.py modified; restarting server
[I 160528 22:47:14 autoreload:204] C:\Python27\lib\urllib.py modified; restarting server
[E 160529 12:39:07 web:1496] Uncaught exception POST /index (127.0.0.1)
    HTTPServerRequest(protocol='http', host='127.0.0.1:15001', method='POST', uri='/index', version='HTTP/1.1', remote_ip='127.0.0.1', headers={'Content-Length': '167', 'Accept-Language': 'en-US,en;q=0.5', 'Accept-Encoding': 'gzip, deflate', 'Host': '127.0.0.1:15001', 'Accept': 'text/html,application/xhtml+xml,application/xml;q=0.9,*/*;q=0.8', 'User-Agent': 'Mozilla/5.0 (Windows NT 6.1; WOW64; rv:46.0) Gecko/20100101 Firefox/46.0', 'Connection': 'keep-alive', 'Referer': 'http://127.0.0.1:15001/', 'Content-Type': 'application/x-www-form-urlencoded'})
    Traceback (most recent call last):
      File "C:\Python27\lib\site-packages\tornado\web.py", line 1369, in _stack_context_handle_exception
        raise_exc_info((type, value, traceback))
      File "C:\Python27\lib\site-packages\tornado\stack_context.py", line 314, in wrapped
        ret = fn(*args, **kwargs)
      File "C:\Python27\lib\site-packages\tornado\gen.py", line 149, in final_callback
        if future.result() is not None:
      File "C:\Python27\lib\site-packages\tornado\concurrent.py", line 215, in result
        raise_exc_info(self._exc_info)
      File "C:\Python27\lib\site-packages\tornado\gen.py", line 215, in wrapper
        result = func(*args, **kwargs)
      File "E:/soheil/web_site_root/ieee/all_functions/tornado-get.py", line 521, in post
        result = tornado.gen.Task(self.download(details))
      File "E:/soheil/web_site_root/ieee/all_functions/tornado-get.py", line 592, in download
        water_pdfdir=root+water_pdfdir,)
      File "E:/soheil/web_site_root/ieee/all_functions\main_core.py", line 169, in valid_link
        responce= self.Find_Link(self.url,pdfdir=pdf_download_location,water_pdfdir=wat_locatton,cookies=cookies).find_link(self.pr,self.us_pss)
      File "E:/soheil/web_site_root/ieee/all_functions\find_link.py", line 262, in find_link
        res = self.new_module.LINK(url).get_pdf_link(proxy, user_pass)
      File "E:/soheil/web_site_root/ieee/all_functions/configs/Links_site/www_sciencedirect_com.py", line 3162, in get_pdf_link
        [html, cookies, links, title, form, time_diff, log_out] = twil_find_pdf_link(url)
      File "E:/soheil/web_site_root/ieee/all_functions/configs/Links_site/www_sciencedirect_com.py", line 1260, in twil_find_pdf_link
        [html, cookies, links, title, times, log_out] = tw.twill_find_link(link, form[k])
      File "E:/soheil/web_site_root/ieee/all_functions/configs/Links_site/www_sciencedirect_com.py", line 2566, in twill_find_link
        t_brw.follow_link(t)
      File "C:\Python27\lib\site-packages\twill-0.9.1-py2.7.egg\twill\browser.py", line 207, in follow_link
        self._journey('follow_link', link)
      File "C:\Python27\lib\site-packages\twill-0.9.1-py2.7.egg\twill\browser.py", line 523, in _journey
        r = func(*args, **kwargs)
      File "C:\Python27\lib\site-packages\twill-0.9.1-py2.7.egg\twill\other_packages\_mechanize_dist\_mechanize.py", line 577, in follow_link
        return self.open(self.click_link(link, **kwds))
      File "C:\Python27\lib\site-packages\twill-0.9.1-py2.7.egg\twill\other_packages\_mechanize_dist\_mechanize.py", line 212, in open
        return self._mech_open(url, data)
      File "C:\Python27\lib\site-packages\twill-0.9.1-py2.7.egg\twill\other_packages\_mechanize_dist\_mechanize.py", line 257, in _mech_open
        self._set_response(response, False)
      File "C:\Python27\lib\site-packages\twill-0.9.1-py2.7.egg\twill\other_packages\_mechanize_dist\_mechanize.py", line 316, in _set_response
        self._factory.set_response(response)
      File "C:\Python27\lib\site-packages\twill-0.9.1-py2.7.egg\twill\utils.py", line 325, in set_response
        self.factory.set_response(cleaned_response)
      File "C:\Python27\lib\site-packages\twill-0.9.1-py2.7.egg\twill\other_packages\_mechanize_dist\_html.py", line 602, in set_response
        soup = self._soup_class(self.encoding, data)
      File "C:\Python27\lib\site-packages\twill-0.9.1-py2.7.egg\twill\other_packages\_mechanize_dist\_html.py", line 314, in __init__
        self, text, avoidParserProblems, initialTextIsEverything)
      File "C:\Python27\lib\site-packages\twill-0.9.1-py2.7.egg\twill\other_packages\_mechanize_dist\_beautifulsoup.py", line 674, in __init__
        self.feed(text)
      File "C:\Python27\lib\site-packages\twill-0.9.1-py2.7.egg\twill\other_packages\_mechanize_dist\_beautifulsoup.py", line 693, in feed
        SGMLParser.feed(self, text)
      File "C:\Python27\lib\sgmllib.py", line 104, in feed
        self.goahead(0)
      File "C:\Python27\lib\sgmllib.py", line 186, in goahead
        self.handle_charref(name)
      File "C:\Python27\lib\site-packages\twill-0.9.1-py2.7.egg\twill\other_packages\_mechanize_dist\_html.py", line 317, in handle_charref
        t = unescape("&#%s;"%ref, self._entitydefs, self._encoding)
      File "C:\Python27\lib\site-packages\twill-0.9.1-py2.7.egg\twill\other_packages\_mechanize_dist\_html.py", line 274, in unescape
        return re.sub(r"&#?[A-Za-z0-9]+?;", replace_entities, data)
      File "C:\Python27\lib\re.py", line 155, in sub
        return _compile(pattern, flags).sub(repl, string, count)
      File "C:\Python27\lib\site-packages\twill-0.9.1-py2.7.egg\twill\other_packages\_mechanize_dist\_html.py", line 260, in replace_entities
        return unescape_charref(ent[2:-1], encoding)
      File "C:\Python27\lib\site-packages\twill-0.9.1-py2.7.egg\twill\other_packages\_mechanize_dist\_html.py", line 280, in unescape_charref
        uc = unichr(int(name, base))
    ValueError: invalid literal for int() with base 10: 'd'
[E 160529 12:39:07 web:1908] 500 POST /index (127.0.0.1) 888715.00ms
[I 160529 13:02:34 web:1908] 200 POST /index (127.0.0.1) 109923.00ms
[W 160529 13:02:35 web:1908] 404 GET /htmls/simple_cursor.css (127.0.0.1) 34.00ms
[E 160529 13:03:44 concurrent:124] Future exception was never retrieved: Traceback (most recent call last):
      File "C:\Python27\lib\site-packages\tornado\gen.py", line 505, in Task
        func(*args, callback=_argument_adapter(set_result), **kwargs)
    TypeError: 'dict' object is not callable
[E 160529 13:29:43 web:2584] Could not open static file 'E:\\soheil\\web_site_root\\ieee\\all_functions\\static\\1-s2.0-S0147596715001304-main.pdf'
[I 160529 13:29:43 web:1908] 200 POST /index (127.0.0.1) 830410.00ms
[W 160529 13:29:44 web:1908] 404 GET /htmls/simple_cursor.css (127.0.0.1) 19.00ms
[I 160529 13:38:01 autoreload:204] E:/soheil/web_site_root/ieee/all_functions/configs/Links_site/www_sciencedirect_com.py modified; restarting server
[E 160529 13:51:18 web:2584] Could not open static file 'E:\\soheil\\web_site_root\\ieee\\all_functions\\static\\1-s2.0-S0147596715001304-main.pdf'
[I 160529 13:51:18 web:1908] 200 POST /index (127.0.0.1) 123374.00ms
[W 160529 13:51:19 web:1908] 404 GET /htmls/simple_cursor.css (127.0.0.1) 97.00ms
[E 160529 13:52:13 concurrent:124] Future exception was never retrieved: Traceback (most recent call last):
      File "C:\Python27\lib\site-packages\tornado\gen.py", line 505, in Task
        func(*args, callback=_argument_adapter(set_result), **kwargs)
    TypeError: 'dict' object is not callable
[E 160529 13:59:04 web:1496] Uncaught exception POST /index (127.0.0.1)
    HTTPServerRequest(protocol='http', host='127.0.0.1:15001', method='POST', uri='/index', version='HTTP/1.1', remote_ip='127.0.0.1', headers={'Content-Length': '173', 'Accept-Language': 'en-US,en;q=0.5', 'Accept-Encoding': 'gzip, deflate', 'Host': '127.0.0.1:15001', 'Accept': 'text/html,application/xhtml+xml,application/xml;q=0.9,*/*;q=0.8', 'User-Agent': 'Mozilla/5.0 (Windows NT 6.1; WOW64; rv:46.0) Gecko/20100101 Firefox/46.0', 'Connection': 'keep-alive', 'Referer': 'http://127.0.0.1:15001/', 'Content-Type': 'application/x-www-form-urlencoded'})
    Traceback (most recent call last):
      File "C:\Python27\lib\site-packages\tornado\web.py", line 1369, in _stack_context_handle_exception
        raise_exc_info((type, value, traceback))
      File "C:\Python27\lib\site-packages\tornado\stack_context.py", line 314, in wrapped
        ret = fn(*args, **kwargs)
      File "C:\Python27\lib\site-packages\tornado\gen.py", line 149, in final_callback
        if future.result() is not None:
      File "C:\Python27\lib\site-packages\tornado\concurrent.py", line 215, in result
        raise_exc_info(self._exc_info)
      File "C:\Python27\lib\site-packages\tornado\gen.py", line 215, in wrapper
        result = func(*args, **kwargs)
      File "E:/soheil/web_site_root/ieee/all_functions/tornado-get.py", line 521, in post
        result = tornado.gen.Task(self.download(details))
      File "E:/soheil/web_site_root/ieee/all_functions/tornado-get.py", line 666, in download
        proxy=proxy,user_pass=user_pass,cookies=cookies,log_out=log_out,ftp_upload=ftp_upload,html=html)
      File "E:/soheil/web_site_root/ieee/all_functions\main_core.py", line 398, in download_link
        pdf_dw_dir, pdf_dw_Wr_dir = PDF_File(url,pdf_download_location,wat_locatton).finall_file_saving(html, file_name,pdf_download_location,no_watermarker=0)
      File "E:/soheil/web_site_root/ieee/all_functions\save_source.py", line 328, in finall_file_saving
        self.pdf_watermark_fast(localName.pdf_Folder_filename, localName.W_pdf_Folder_filename,url_wtm=url_watermark)
      File "E:/soheil/web_site_root/ieee/all_functions\save_source.py", line 171, in pdf_watermark_fast
        wt1 = self.watermark_file(self.Watermarked_PDF_Dir+"/" + "watermarker_slow"+url_watermark+".pdf", url_watermark,center_text=False)
      File "E:/soheil/web_site_root/ieee/all_functions\save_source.py", line 116, in watermark_file
        from reportlab.pdfgen import canvas
    ImportError: No module named reportlab.pdfgen
[E 160529 13:59:04 web:1908] 500 POST /index (127.0.0.1) 440554.00ms
[I 160529 13:59:04 autoreload:204] E:/soheil/web_site_root/ieee/all_functions/configs/Links_site/www_sciencedirect_com.py modified; restarting server
[E 160529 14:12:45 web:1496] Uncaught exception POST /index (127.0.0.1)
    HTTPServerRequest(protocol='http', host='127.0.0.1:15001', method='POST', uri='/index', version='HTTP/1.1', remote_ip='127.0.0.1', headers={'Content-Length': '173', 'Accept-Language': 'en-US,en;q=0.5', 'Accept-Encoding': 'gzip, deflate', 'Host': '127.0.0.1:15001', 'Accept': 'text/html,application/xhtml+xml,application/xml;q=0.9,*/*;q=0.8', 'User-Agent': 'Mozilla/5.0 (Windows NT 6.1; WOW64; rv:46.0) Gecko/20100101 Firefox/46.0', 'Connection': 'keep-alive', 'Referer': 'http://127.0.0.1:15001/', 'Content-Type': 'application/x-www-form-urlencoded'})
    Traceback (most recent call last):
      File "C:\Python27\lib\site-packages\tornado\web.py", line 1369, in _stack_context_handle_exception
        raise_exc_info((type, value, traceback))
      File "C:\Python27\lib\site-packages\tornado\stack_context.py", line 314, in wrapped
        ret = fn(*args, **kwargs)
      File "C:\Python27\lib\site-packages\tornado\gen.py", line 149, in final_callback
        if future.result() is not None:
      File "C:\Python27\lib\site-packages\tornado\concurrent.py", line 215, in result
        raise_exc_info(self._exc_info)
      File "C:\Python27\lib\site-packages\tornado\gen.py", line 215, in wrapper
        result = func(*args, **kwargs)
      File "E:/soheil/web_site_root/ieee/all_functions/tornado-get.py", line 521, in post
        result = tornado.gen.Task(self.download(details))
      File "E:/soheil/web_site_root/ieee/all_functions/tornado-get.py", line 666, in download
        proxy=proxy,user_pass=user_pass,cookies=cookies,log_out=log_out,ftp_upload=ftp_upload,html=html)
      File "E:/soheil/web_site_root/ieee/all_functions\main_core.py", line 398, in download_link
        pdf_dw_dir, pdf_dw_Wr_dir = PDF_File(url,pdf_download_location,wat_locatton).finall_file_saving(html, file_name,pdf_download_location,no_watermarker=0)
      File "E:/soheil/web_site_root/ieee/all_functions\save_source.py", line 328, in finall_file_saving
        self.pdf_watermark_fast(localName.pdf_Folder_filename, localName.W_pdf_Folder_filename,url_wtm=url_watermark)
      File "E:/soheil/web_site_root/ieee/all_functions\save_source.py", line 171, in pdf_watermark_fast
        wt1 = self.watermark_file(self.Watermarked_PDF_Dir+"/" + "watermarker_slow"+url_watermark+".pdf", url_watermark,center_text=False)
      File "E:/soheil/web_site_root/ieee/all_functions\save_source.py", line 116, in watermark_file
        from reportlab.pdfgen import canvas
    ImportError: No module named reportlab.pdfgen
[E 160529 14:12:45 web:1908] 500 POST /index (127.0.0.1) 640228.00ms
[E 160529 14:24:20 web:1496] Uncaught exception POST /index (127.0.0.1)
    HTTPServerRequest(protocol='http', host='127.0.0.1:15001', method='POST', uri='/index', version='HTTP/1.1', remote_ip='127.0.0.1', headers={'Content-Length': '173', 'Accept-Language': 'en-US,en;q=0.5', 'Accept-Encoding': 'gzip, deflate', 'Host': '127.0.0.1:15001', 'Accept': 'text/html,application/xhtml+xml,application/xml;q=0.9,*/*;q=0.8', 'User-Agent': 'Mozilla/5.0 (Windows NT 6.1; WOW64; rv:46.0) Gecko/20100101 Firefox/46.0', 'Connection': 'keep-alive', 'Referer': 'http://127.0.0.1:15001/', 'Content-Type': 'application/x-www-form-urlencoded'})
    Traceback (most recent call last):
      File "C:\Python27\lib\site-packages\tornado\web.py", line 1369, in _stack_context_handle_exception
        raise_exc_info((type, value, traceback))
      File "C:\Python27\lib\site-packages\tornado\stack_context.py", line 314, in wrapped
        ret = fn(*args, **kwargs)
      File "C:\Python27\lib\site-packages\tornado\gen.py", line 149, in final_callback
        if future.result() is not None:
      File "C:\Python27\lib\site-packages\tornado\concurrent.py", line 215, in result
        raise_exc_info(self._exc_info)
      File "C:\Python27\lib\site-packages\tornado\gen.py", line 215, in wrapper
        result = func(*args, **kwargs)
      File "E:/soheil/web_site_root/ieee/all_functions/tornado-get.py", line 521, in post
        result = tornado.gen.Task(self.download(details))
      File "E:/soheil/web_site_root/ieee/all_functions/tornado-get.py", line 666, in download
        proxy=proxy,user_pass=user_pass,cookies=cookies,log_out=log_out,ftp_upload=ftp_upload,html=html)
      File "E:/soheil/web_site_root/ieee/all_functions\main_core.py", line 398, in download_link
        pdf_dw_dir, pdf_dw_Wr_dir = PDF_File(url,pdf_download_location,wat_locatton).finall_file_saving(html, file_name,pdf_download_location,no_watermarker=0)
      File "E:/soheil/web_site_root/ieee/all_functions\save_source.py", line 328, in finall_file_saving
        self.pdf_watermark_fast(localName.pdf_Folder_filename, localName.W_pdf_Folder_filename,url_wtm=url_watermark)
      File "E:/soheil/web_site_root/ieee/all_functions\save_source.py", line 171, in pdf_watermark_fast
        wt1 = self.watermark_file(self.Watermarked_PDF_Dir+"/" + "watermarker_slow"+url_watermark+".pdf", url_watermark,center_text=False)
      File "E:/soheil/web_site_root/ieee/all_functions\save_source.py", line 116, in watermark_file
        from reportlab.pdfgen import canvas
    ImportError: No module named reportlab.pdfgen
[E 160529 14:24:20 web:1908] 500 POST /index (127.0.0.1) 469269.00ms
[W 160529 15:11:42 web:1908] 404 GET /Watermarked_PDF_Files (127.0.0.1) 7.00ms
[W 160529 15:12:02 web:1908] 404 GET /Watermarked_PDF_Files (127.0.0.1) 4.00ms
[I 160529 15:12:21 web:1908] 200 GET /download (127.0.0.1) 32.00ms
[I 160529 15:22:22 autoreload:204] E:/soheil/web_site_root/ieee/all_functions/tornado-get.py modified; restarting server
[E 160529 15:25:46 web:1496] Uncaught exception GET /static (127.0.0.1)
    HTTPServerRequest(protocol='http', host='127.0.0.1:15001', method='GET', uri='/static', version='HTTP/1.1', remote_ip='127.0.0.1', headers={'Connection': 'keep-alive', 'Accept-Language': 'en-US,en;q=0.5', 'Accept-Encoding': 'gzip, deflate', 'Host': '127.0.0.1:15001', 'Accept': 'text/html,application/xhtml+xml,application/xml;q=0.9,*/*;q=0.8', 'User-Agent': 'Mozilla/5.0 (Windows NT 6.1; WOW64; rv:46.0) Gecko/20100101 Firefox/46.0'})
    Traceback (most recent call last):
      File "C:\Python27\lib\site-packages\tornado\web.py", line 1415, in _execute
        result = yield result
      File "C:\Python27\lib\site-packages\tornado\gen.py", line 870, in run
        value = future.result()
      File "C:\Python27\lib\site-packages\tornado\concurrent.py", line 215, in result
        raise_exc_info(self._exc_info)
      File "C:\Python27\lib\site-packages\tornado\gen.py", line 215, in wrapper
        result = func(*args, **kwargs)
    TypeError: get() takes at least 2 arguments (1 given)
[E 160529 15:25:46 web:1908] 500 GET /static (127.0.0.1) 155.00ms
[I 160529 15:26:29 web:1908] 200 GET /static/watermarker_slowsoheil.pdf (127.0.0.1) 11699.00ms
[W 160529 15:27:38 web:1908] 404 GET /PDF_Files/watermarker_slowsoheil.pdf (127.0.0.1) 8.00ms
[W 160529 15:27:38 web:1908] 404 GET /PDF_Files/watermarker_slowsoheil.pdf (127.0.0.1) 3.00ms
[W 160529 15:27:38 web:1908] 404 GET /PDF_Files/watermarker_slowsoheil.pdf (127.0.0.1) 3.00ms
[W 160529 15:27:42 web:1908] 404 GET /PDF_Files/watermarker_slowsoheil.pdf (127.0.0.1) 4.00ms
[W 160529 15:27:51 web:1908] 404 GET /PDF_Files/watermarker_slowsoheil.pdf (127.0.0.1) 3.00ms
[W 160529 15:27:51 web:1908] 404 GET /PDF_Files/watermarker_slowsoheil.pdf (127.0.0.1) 3.00ms
[W 160529 15:27:51 web:1908] 404 GET /PDF_Files/watermarker_slowsoheil.pdf (127.0.0.1) 3.00ms
[I 160529 15:28:12 autoreload:204] E:/soheil/web_site_root/ieee/all_functions/tornado-get.py modified; restarting server
[W 160529 15:29:22 web:1908] 404 GET /PDF_Files/watermarker_slowsoheil.pdf (127.0.0.1) 10.00ms
[W 160529 15:29:22 web:1908] 404 GET /PDF_Files/watermarker_slowsoheil.pdf (127.0.0.1) 7.00ms
[W 160529 15:29:22 web:1908] 404 GET /PDF_Files/watermarker_slowsoheil.pdf (127.0.0.1) 4.00ms
[W 160529 15:29:29 web:1908] 404 GET /PDF_Files/watermarker_slowsoheil.pdf (127.0.0.1) 7.00ms
[W 160529 15:29:29 web:1908] 404 GET /PDF_Files/watermarker_slowsoheil.pdf (127.0.0.1) 4.00ms
[W 160529 15:29:29 web:1908] 404 GET /PDF_Files/watermarker_slowsoheil.pdf (127.0.0.1) 5.00ms
[I 160529 15:29:43 web:1908] 200 GET /static/watermarker_slowsoheil.pdf (127.0.0.1) 993.00ms
[W 160529 15:29:59 web:1908] 404 GET /static/watermarker_slowsoheil.pdf (127.0.0.1) 8.00ms
[W 160529 15:29:59 web:1908] 404 GET /static/watermarker_slowsoheil.pdf (127.0.0.1) 6.00ms
[W 160529 15:29:59 web:1908] 404 GET /static/watermarker_slowsoheil.pdf (127.0.0.1) 6.00ms
[I 160529 15:30:21 web:1908] 200 GET /static/watermarker_slowsoheil.pdf (127.0.0.1) 9.00ms
[W 160529 15:30:56 web:1908] 404 GET /static/watermarker_slowsoheil.pdf (127.0.0.1) 10.00ms
[W 160529 15:30:56 web:1908] 404 GET /static/watermarker_slowsoheil.pdf (127.0.0.1) 5.00ms
[W 160529 15:30:56 web:1908] 404 GET /static/watermarker_slowsoheil.pdf (127.0.0.1) 4.00ms
[I 160529 15:31:17 autoreload:204] E:/soheil/web_site_root/ieee/all_functions/tornado-get.py modified; restarting server
[I 160529 15:31:36 web:1908] 200 GET /static/watermarker_slowsoheil.pdf (127.0.0.1) 833.00ms
[I 160529 15:31:54 autoreload:204] E:/soheil/web_site_root/ieee/all_functions/tornado-get.py modified; restarting server
[W 160529 15:32:23 web:1908] 404 GET /PDF_Files/watermarker_slowsoheil.pdf (127.0.0.1) 7.00ms
[W 160529 15:32:23 web:1908] 404 GET /PDF_Files/watermarker_slowsoheil.pdf (127.0.0.1) 5.00ms
[W 160529 15:32:23 web:1908] 404 GET /PDF_Files/watermarker_slowsoheil.pdf (127.0.0.1) 5.00ms
[W 160529 15:32:26 web:1908] 404 GET /PDF_Files/watermarker_slowsoheil.pdf (127.0.0.1) 3.00ms
[I 160529 15:36:14 web:1908] 200 GET /PDF_Files/watermarker_slowsoheil.pdf (127.0.0.1) 887.00ms
[I 160529 15:36:37 web:1908] 200 GET /PDF_Files/watermarker_slowsoheil.pdf (127.0.0.1) 766.00ms
[I 160529 15:36:43 web:1908] 200 GET /static/watermarker_slowsoheil.pdf (127.0.0.1) 11.00ms
[I 160529 16:18:07 web:1908] 200 GET /index (127.0.0.1) 379.00ms
[E 160529 16:18:07 web:1496] Uncaught exception GET /index (127.0.0.1)
    HTTPServerRequest(protocol='http', host='127.0.0.1:15001', method='GET', uri='/index', version='HTTP/1.1', remote_ip='127.0.0.1', headers={'Connection': 'keep-alive', 'Accept-Language': 'en-US,en;q=0.5', 'Accept-Encoding': 'gzip, deflate', 'Host': '127.0.0.1:15001', 'Accept': 'text/html,application/xhtml+xml,application/xml;q=0.9,*/*;q=0.8', 'User-Agent': 'Mozilla/5.0 (Windows NT 6.1; WOW64; rv:46.0) Gecko/20100101 Firefox/46.0'})
    Traceback (most recent call last):
      File "C:\Python27\lib\site-packages\tornado\web.py", line 1369, in _stack_context_handle_exception
        raise_exc_info((type, value, traceback))
      File "C:\Python27\lib\site-packages\tornado\stack_context.py", line 314, in wrapped
        ret = fn(*args, **kwargs)
      File "C:\Python27\lib\site-packages\tornado\gen.py", line 149, in final_callback
        if future.result() is not None:
      File "C:\Python27\lib\site-packages\tornado\concurrent.py", line 215, in result
        raise_exc_info(self._exc_info)
      File "C:\Python27\lib\site-packages\tornado\gen.py", line 215, in wrapper
        result = func(*args, **kwargs)
      File "E:/soheil/web_site_root/ieee/all_functions/tornado-get.py", line 945, in get
        self.finish()
      File "C:\Python27\lib\site-packages\tornado\web.py", line 905, in finish
        raise RuntimeError("finish() called twice")
    RuntimeError: finish() called twice
[W 160529 16:18:07 web:1908] 404 GET /favicon.ico (127.0.0.1) 6.00ms
[W 160529 16:18:07 web:1908] 404 GET /favicon.ico (127.0.0.1) 4.00ms
[I 160529 16:23:05 web:1908] 200 POST /index (127.0.0.1) 246985.00ms
[W 160529 16:23:05 web:1908] 404 GET /htmls/simple_cursor.css (127.0.0.1) 5.00ms
[W 160529 16:23:05 web:1908] 404 GET /htmls/simple_cursor.css (127.0.0.1) 3.00ms
[I 160529 17:12:39 autoreload:204] E:/soheil/web_site_root/ieee/all_functions/configs/Links_site/www_sciencedirect_com.py modified; restarting server
[I 160529 17:20:28 web:1908] 200 GET /index (127.0.0.1) 31.00ms
[E 160529 17:20:28 web:1496] Uncaught exception GET /index (127.0.0.1)
    HTTPServerRequest(protocol='http', host='127.0.0.1:15001', method='GET', uri='/index', version='HTTP/1.1', remote_ip='127.0.0.1', headers={'Connection': 'keep-alive', 'Accept-Language': 'en-US,en;q=0.5', 'Accept-Encoding': 'gzip, deflate', 'Host': '127.0.0.1:15001', 'Accept': 'text/html,application/xhtml+xml,application/xml;q=0.9,*/*;q=0.8', 'User-Agent': 'Mozilla/5.0 (Windows NT 6.1; WOW64; rv:46.0) Gecko/20100101 Firefox/46.0'})
    Traceback (most recent call last):
      File "C:\Python27\lib\site-packages\tornado\web.py", line 1369, in _stack_context_handle_exception
        raise_exc_info((type, value, traceback))
      File "C:\Python27\lib\site-packages\tornado\stack_context.py", line 314, in wrapped
        ret = fn(*args, **kwargs)
      File "C:\Python27\lib\site-packages\tornado\gen.py", line 149, in final_callback
        if future.result() is not None:
      File "C:\Python27\lib\site-packages\tornado\concurrent.py", line 215, in result
        raise_exc_info(self._exc_info)
      File "C:\Python27\lib\site-packages\tornado\gen.py", line 215, in wrapper
        result = func(*args, **kwargs)
      File "E:/soheil/web_site_root/ieee/all_functions/tornado-get.py", line 945, in get
        self.finish()
      File "C:\Python27\lib\site-packages\tornado\web.py", line 905, in finish
        raise RuntimeError("finish() called twice")
    RuntimeError: finish() called twice
[I 160529 17:30:29 web:1908] 200 POST /index (127.0.0.1) 598399.00ms
[W 160529 17:30:29 web:1908] 404 GET /htmls/simple_cursor.css (127.0.0.1) 6.00ms
[W 160529 17:30:30 web:1908] 404 GET /htmls/simple_cursor.css (127.0.0.1) 3.00ms
[I 160529 17:30:51 web:1908] 200 GET /index (127.0.0.1) 18.00ms
[E 160529 17:30:51 web:1496] Uncaught exception GET /index (127.0.0.1)
    HTTPServerRequest(protocol='http', host='127.0.0.1:15001', method='GET', uri='/index', version='HTTP/1.1', remote_ip='127.0.0.1', headers={'Connection': 'keep-alive', 'Accept-Language': 'en-US,en;q=0.5', 'Accept-Encoding': 'gzip, deflate', 'Host': '127.0.0.1:15001', 'Accept': 'text/html,application/xhtml+xml,application/xml;q=0.9,*/*;q=0.8', 'User-Agent': 'Mozilla/5.0 (Windows NT 6.1; WOW64; rv:46.0) Gecko/20100101 Firefox/46.0'})
    Traceback (most recent call last):
      File "C:\Python27\lib\site-packages\tornado\web.py", line 1369, in _stack_context_handle_exception
        raise_exc_info((type, value, traceback))
      File "C:\Python27\lib\site-packages\tornado\stack_context.py", line 314, in wrapped
        ret = fn(*args, **kwargs)
      File "C:\Python27\lib\site-packages\tornado\gen.py", line 149, in final_callback
        if future.result() is not None:
      File "C:\Python27\lib\site-packages\tornado\concurrent.py", line 215, in result
        raise_exc_info(self._exc_info)
      File "C:\Python27\lib\site-packages\tornado\gen.py", line 215, in wrapper
        result = func(*args, **kwargs)
      File "E:/soheil/web_site_root/ieee/all_functions/tornado-get.py", line 945, in get
        self.finish()
      File "C:\Python27\lib\site-packages\tornado\web.py", line 905, in finish
        raise RuntimeError("finish() called twice")
    RuntimeError: finish() called twice
[E 160529 17:31:09 concurrent:124] Future exception was never retrieved: Traceback (most recent call last):
      File "C:\Python27\lib\site-packages\tornado\gen.py", line 505, in Task
        func(*args, callback=_argument_adapter(set_result), **kwargs)
    TypeError: 'dict' object is not callable
[E 160529 21:23:53 web:1496] Uncaught exception POST /index (127.0.0.1)
    HTTPServerRequest(protocol='http', host='127.0.0.1:15001', method='POST', uri='/index', version='HTTP/1.1', remote_ip='127.0.0.1', headers={'Content-Length': '167', 'Accept-Language': 'en-US,en;q=0.5', 'Accept-Encoding': 'gzip, deflate', 'Host': '127.0.0.1:15001', 'Accept': 'text/html,application/xhtml+xml,application/xml;q=0.9,*/*;q=0.8', 'User-Agent': 'Mozilla/5.0 (Windows NT 6.1; WOW64; rv:46.0) Gecko/20100101 Firefox/46.0', 'Connection': 'keep-alive', 'Referer': 'http://127.0.0.1:15001/index', 'Content-Type': 'application/x-www-form-urlencoded'})
    Traceback (most recent call last):
      File "C:\Python27\lib\site-packages\tornado\web.py", line 1369, in _stack_context_handle_exception
        raise_exc_info((type, value, traceback))
      File "C:\Python27\lib\site-packages\tornado\stack_context.py", line 314, in wrapped
        ret = fn(*args, **kwargs)
      File "C:\Python27\lib\site-packages\tornado\gen.py", line 149, in final_callback
        if future.result() is not None:
      File "C:\Python27\lib\site-packages\tornado\concurrent.py", line 215, in result
        raise_exc_info(self._exc_info)
      File "C:\Python27\lib\site-packages\tornado\gen.py", line 215, in wrapper
        result = func(*args, **kwargs)
      File "E:/soheil/web_site_root/ieee/all_functions/tornado-get.py", line 521, in post
        result = tornado.gen.Task(self.download(details))
      File "E:/soheil/web_site_root/ieee/all_functions/tornado-get.py", line 592, in download
        water_pdfdir=root+water_pdfdir,)
      File "E:/soheil/web_site_root/ieee/all_functions\main_core.py", line 169, in valid_link
        responce= self.Find_Link(self.url,pdfdir=pdf_download_location,water_pdfdir=wat_locatton,cookies=cookies).find_link(self.pr,self.us_pss)
      File "E:/soheil/web_site_root/ieee/all_functions\find_link.py", line 262, in find_link
        res = self.new_module.LINK(url).get_pdf_link(proxy, user_pass)
      File "E:/soheil/web_site_root/ieee/all_functions/configs/Links_site/www_sciencedirect_com.py", line 3172, in get_pdf_link
        [html, cookies, links, title, form, time_diff, log_out] = twil_find_pdf_link(url)
      File "E:/soheil/web_site_root/ieee/all_functions/configs/Links_site/www_sciencedirect_com.py", line 1266, in twil_find_pdf_link
        os.remove(cookies)
    WindowsError: [Error 2] The system cannot find the file specified: 'E:/soheil/web_site_root/ieee/all_functions/configs/sites_proxy/www.sciencedirect.com/cookies/nZqmp.txt'
[E 160529 21:23:54 web:1908] 500 POST /index (127.0.0.1) 12264696.00ms
[I 160530 18:58:01 web:1908] 200 GET /index (127.0.0.1) 149.00ms
[E 160530 18:58:01 web:1496] Uncaught exception GET /index (127.0.0.1)
    HTTPServerRequest(protocol='http', host='127.0.0.1:15001', method='GET', uri='/index', version='HTTP/1.1', remote_ip='127.0.0.1', headers={'Connection': 'keep-alive', 'Accept-Language': 'en-US,en;q=0.5', 'Accept-Encoding': 'gzip, deflate', 'Host': '127.0.0.1:15001', 'Accept': 'text/html,application/xhtml+xml,application/xml;q=0.9,*/*;q=0.8', 'User-Agent': 'Mozilla/5.0 (Windows NT 6.1; WOW64; rv:46.0) Gecko/20100101 Firefox/46.0'})
    Traceback (most recent call last):
      File "C:\Python27\lib\site-packages\tornado\web.py", line 1369, in _stack_context_handle_exception
        raise_exc_info((type, value, traceback))
      File "C:\Python27\lib\site-packages\tornado\stack_context.py", line 314, in wrapped
        ret = fn(*args, **kwargs)
      File "C:\Python27\lib\site-packages\tornado\gen.py", line 149, in final_callback
        if future.result() is not None:
      File "C:\Python27\lib\site-packages\tornado\concurrent.py", line 215, in result
        raise_exc_info(self._exc_info)
      File "C:\Python27\lib\site-packages\tornado\gen.py", line 215, in wrapper
        result = func(*args, **kwargs)
      File "E:/soheil/web_site_root/ieee/all_functions/tornado-get.py", line 945, in get
        self.finish()
      File "C:\Python27\lib\site-packages\tornado\web.py", line 905, in finish
        raise RuntimeError("finish() called twice")
    RuntimeError: finish() called twice
[W 160530 18:58:02 web:1908] 404 GET /favicon.ico (127.0.0.1) 23.00ms
[W 160530 18:58:02 web:1908] 404 GET /favicon.ico (127.0.0.1) 5.00ms
[E 160530 18:58:06 web:1496] Uncaught exception POST /index (127.0.0.1)
    HTTPServerRequest(protocol='http', host='127.0.0.1:15001', method='POST', uri='/index', version='HTTP/1.1', remote_ip='127.0.0.1', headers={'Content-Length': '167', 'Accept-Language': 'en-US,en;q=0.5', 'Accept-Encoding': 'gzip, deflate', 'Host': '127.0.0.1:15001', 'Accept': 'text/html,application/xhtml+xml,application/xml;q=0.9,*/*;q=0.8', 'User-Agent': 'Mozilla/5.0 (Windows NT 6.1; WOW64; rv:46.0) Gecko/20100101 Firefox/46.0', 'Connection': 'keep-alive', 'Referer': 'http://127.0.0.1:15001/index', 'Content-Type': 'application/x-www-form-urlencoded'})
    Traceback (most recent call last):
      File "C:\Python27\lib\site-packages\tornado\web.py", line 1369, in _stack_context_handle_exception
        raise_exc_info((type, value, traceback))
      File "C:\Python27\lib\site-packages\tornado\stack_context.py", line 314, in wrapped
        ret = fn(*args, **kwargs)
      File "C:\Python27\lib\site-packages\tornado\gen.py", line 149, in final_callback
        if future.result() is not None:
      File "C:\Python27\lib\site-packages\tornado\concurrent.py", line 215, in result
        raise_exc_info(self._exc_info)
      File "C:\Python27\lib\site-packages\tornado\gen.py", line 215, in wrapper
        result = func(*args, **kwargs)
      File "E:/soheil/web_site_root/ieee/all_functions/tornado-get.py", line 521, in post
        result = tornado.gen.Task(self.download(details))
      File "E:/soheil/web_site_root/ieee/all_functions/tornado-get.py", line 592, in download
        water_pdfdir=root+water_pdfdir,)
      File "E:/soheil/web_site_root/ieee/all_functions\main_core.py", line 169, in valid_link
        responce= self.Find_Link(self.url,pdfdir=pdf_download_location,water_pdfdir=wat_locatton,cookies=cookies).find_link(self.pr,self.us_pss)
      File "E:/soheil/web_site_root/ieee/all_functions\find_link.py", line 262, in find_link
        res = self.new_module.LINK(url).get_pdf_link(proxy, user_pass)
      File "E:/soheil/web_site_root/ieee/all_functions/configs/Links_site/www_sciencedirect_com.py", line 3172, in get_pdf_link
        [html, cookies, links, title, form, time_diff, log_out] = twil_find_pdf_link(url)
      File "E:/soheil/web_site_root/ieee/all_functions/configs/Links_site/www_sciencedirect_com.py", line 1266, in twil_find_pdf_link
        os.remove(cookies)
    UnboundLocalError: local variable 'cookies' referenced before assignment
[E 160530 18:58:06 web:1908] 500 POST /index (127.0.0.1) 2755.00ms
[I 160530 18:58:31 web:1908] 200 GET /index (127.0.0.1) 24.00ms
[E 160530 18:58:31 web:1496] Uncaught exception GET /index (127.0.0.1)
    HTTPServerRequest(protocol='http', host='127.0.0.1:15001', method='GET', uri='/index', version='HTTP/1.1', remote_ip='127.0.0.1', headers={'Connection': 'keep-alive', 'Accept-Language': 'en-US,en;q=0.5', 'Accept-Encoding': 'gzip, deflate', 'Host': '127.0.0.1:15001', 'Accept': 'text/html,application/xhtml+xml,application/xml;q=0.9,*/*;q=0.8', 'User-Agent': 'Mozilla/5.0 (Windows NT 6.1; WOW64; rv:46.0) Gecko/20100101 Firefox/46.0'})
    Traceback (most recent call last):
      File "C:\Python27\lib\site-packages\tornado\web.py", line 1369, in _stack_context_handle_exception
        raise_exc_info((type, value, traceback))
      File "C:\Python27\lib\site-packages\tornado\stack_context.py", line 314, in wrapped
        ret = fn(*args, **kwargs)
      File "C:\Python27\lib\site-packages\tornado\gen.py", line 149, in final_callback
        if future.result() is not None:
      File "C:\Python27\lib\site-packages\tornado\concurrent.py", line 215, in result
        raise_exc_info(self._exc_info)
      File "C:\Python27\lib\site-packages\tornado\gen.py", line 215, in wrapper
        result = func(*args, **kwargs)
      File "E:/soheil/web_site_root/ieee/all_functions/tornado-get.py", line 945, in get
        self.finish()
      File "C:\Python27\lib\site-packages\tornado\web.py", line 905, in finish
        raise RuntimeError("finish() called twice")
    RuntimeError: finish() called twice
[E 160530 18:58:37 web:1496] Uncaught exception POST /index (127.0.0.1)
    HTTPServerRequest(protocol='http', host='127.0.0.1:15001', method='POST', uri='/index', version='HTTP/1.1', remote_ip='127.0.0.1', headers={'Content-Length': '171', 'Accept-Language': 'en-US,en;q=0.5', 'Accept-Encoding': 'gzip, deflate', 'Host': '127.0.0.1:15001', 'Accept': 'text/html,application/xhtml+xml,application/xml;q=0.9,*/*;q=0.8', 'User-Agent': 'Mozilla/5.0 (Windows NT 6.1; WOW64; rv:46.0) Gecko/20100101 Firefox/46.0', 'Connection': 'keep-alive', 'Referer': 'http://127.0.0.1:15001/index', 'Content-Type': 'application/x-www-form-urlencoded'})
    Traceback (most recent call last):
      File "C:\Python27\lib\site-packages\tornado\web.py", line 1369, in _stack_context_handle_exception
        raise_exc_info((type, value, traceback))
      File "C:\Python27\lib\site-packages\tornado\stack_context.py", line 314, in wrapped
        ret = fn(*args, **kwargs)
      File "C:\Python27\lib\site-packages\tornado\gen.py", line 149, in final_callback
        if future.result() is not None:
      File "C:\Python27\lib\site-packages\tornado\concurrent.py", line 215, in result
        raise_exc_info(self._exc_info)
      File "C:\Python27\lib\site-packages\tornado\gen.py", line 215, in wrapper
        result = func(*args, **kwargs)
      File "E:/soheil/web_site_root/ieee/all_functions/tornado-get.py", line 521, in post
        result = tornado.gen.Task(self.download(details))
      File "E:/soheil/web_site_root/ieee/all_functions/tornado-get.py", line 592, in download
        water_pdfdir=root+water_pdfdir,)
      File "E:/soheil/web_site_root/ieee/all_functions\main_core.py", line 169, in valid_link
        responce= self.Find_Link(self.url,pdfdir=pdf_download_location,water_pdfdir=wat_locatton,cookies=cookies).find_link(self.pr,self.us_pss)
      File "E:/soheil/web_site_root/ieee/all_functions\find_link.py", line 262, in find_link
        res = self.new_module.LINK(url).get_pdf_link(proxy, user_pass)
      File "E:/soheil/web_site_root/ieee/all_functions/configs/Links_site/www_sciencedirect_com.py", line 3172, in get_pdf_link
        [html, cookies, links, title, form, time_diff, log_out] = twil_find_pdf_link(url)
      File "E:/soheil/web_site_root/ieee/all_functions/configs/Links_site/www_sciencedirect_com.py", line 1266, in twil_find_pdf_link
        os.remove(cookies)
    UnboundLocalError: local variable 'cookies' referenced before assignment
[E 160530 18:58:37 web:1908] 500 POST /index (127.0.0.1) 1057.00ms
[I 160530 18:58:50 web:1908] 200 GET /index (127.0.0.1) 12.00ms
[E 160530 18:58:50 web:1496] Uncaught exception GET /index (127.0.0.1)
    HTTPServerRequest(protocol='http', host='127.0.0.1:15001', method='GET', uri='/index', version='HTTP/1.1', remote_ip='127.0.0.1', headers={'Connection': 'keep-alive', 'Accept-Language': 'en-US,en;q=0.5', 'Accept-Encoding': 'gzip, deflate', 'Host': '127.0.0.1:15001', 'Accept': 'text/html,application/xhtml+xml,application/xml;q=0.9,*/*;q=0.8', 'User-Agent': 'Mozilla/5.0 (Windows NT 6.1; WOW64; rv:46.0) Gecko/20100101 Firefox/46.0'})
    Traceback (most recent call last):
      File "C:\Python27\lib\site-packages\tornado\web.py", line 1369, in _stack_context_handle_exception
        raise_exc_info((type, value, traceback))
      File "C:\Python27\lib\site-packages\tornado\stack_context.py", line 314, in wrapped
        ret = fn(*args, **kwargs)
      File "C:\Python27\lib\site-packages\tornado\gen.py", line 149, in final_callback
        if future.result() is not None:
      File "C:\Python27\lib\site-packages\tornado\concurrent.py", line 215, in result
        raise_exc_info(self._exc_info)
      File "C:\Python27\lib\site-packages\tornado\gen.py", line 215, in wrapper
        result = func(*args, **kwargs)
      File "E:/soheil/web_site_root/ieee/all_functions/tornado-get.py", line 945, in get
        self.finish()
      File "C:\Python27\lib\site-packages\tornado\web.py", line 905, in finish
        raise RuntimeError("finish() called twice")
    RuntimeError: finish() called twice
[E 160530 18:58:55 web:1496] Uncaught exception POST /index (127.0.0.1)
    HTTPServerRequest(protocol='http', host='127.0.0.1:15001', method='POST', uri='/index', version='HTTP/1.1', remote_ip='127.0.0.1', headers={'Content-Length': '167', 'Accept-Language': 'en-US,en;q=0.5', 'Accept-Encoding': 'gzip, deflate', 'Host': '127.0.0.1:15001', 'Accept': 'text/html,application/xhtml+xml,application/xml;q=0.9,*/*;q=0.8', 'User-Agent': 'Mozilla/5.0 (Windows NT 6.1; WOW64; rv:46.0) Gecko/20100101 Firefox/46.0', 'Connection': 'keep-alive', 'Referer': 'http://127.0.0.1:15001/index', 'Content-Type': 'application/x-www-form-urlencoded'})
    Traceback (most recent call last):
      File "C:\Python27\lib\site-packages\tornado\web.py", line 1369, in _stack_context_handle_exception
        raise_exc_info((type, value, traceback))
      File "C:\Python27\lib\site-packages\tornado\stack_context.py", line 314, in wrapped
        ret = fn(*args, **kwargs)
      File "C:\Python27\lib\site-packages\tornado\gen.py", line 149, in final_callback
        if future.result() is not None:
      File "C:\Python27\lib\site-packages\tornado\concurrent.py", line 215, in result
        raise_exc_info(self._exc_info)
      File "C:\Python27\lib\site-packages\tornado\gen.py", line 215, in wrapper
        result = func(*args, **kwargs)
      File "E:/soheil/web_site_root/ieee/all_functions/tornado-get.py", line 521, in post
        result = tornado.gen.Task(self.download(details))
      File "E:/soheil/web_site_root/ieee/all_functions/tornado-get.py", line 592, in download
        water_pdfdir=root+water_pdfdir,)
      File "E:/soheil/web_site_root/ieee/all_functions\main_core.py", line 169, in valid_link
        responce= self.Find_Link(self.url,pdfdir=pdf_download_location,water_pdfdir=wat_locatton,cookies=cookies).find_link(self.pr,self.us_pss)
      File "E:/soheil/web_site_root/ieee/all_functions\find_link.py", line 262, in find_link
        res = self.new_module.LINK(url).get_pdf_link(proxy, user_pass)
      File "E:/soheil/web_site_root/ieee/all_functions/configs/Links_site/www_sciencedirect_com.py", line 3172, in get_pdf_link
        [html, cookies, links, title, form, time_diff, log_out] = twil_find_pdf_link(url)
      File "E:/soheil/web_site_root/ieee/all_functions/configs/Links_site/www_sciencedirect_com.py", line 1266, in twil_find_pdf_link
        os.remove(cookies)
    UnboundLocalError: local variable 'cookies' referenced before assignment
[E 160530 18:58:55 web:1908] 500 POST /index (127.0.0.1) 1137.00ms
[I 160530 19:00:45 web:1908] 200 GET /index (127.0.0.1) 7.00ms
[E 160530 19:00:45 web:1496] Uncaught exception GET /index (127.0.0.1)
    HTTPServerRequest(protocol='http', host='127.0.0.1:15001', method='GET', uri='/index', version='HTTP/1.1', remote_ip='127.0.0.1', headers={'Connection': 'keep-alive', 'Accept-Language': 'en-US,en;q=0.5', 'Accept-Encoding': 'gzip, deflate', 'Host': '127.0.0.1:15001', 'Accept': 'text/html,application/xhtml+xml,application/xml;q=0.9,*/*;q=0.8', 'User-Agent': 'Mozilla/5.0 (Windows NT 6.1; WOW64; rv:46.0) Gecko/20100101 Firefox/46.0'})
    Traceback (most recent call last):
      File "C:\Python27\lib\site-packages\tornado\web.py", line 1369, in _stack_context_handle_exception
        raise_exc_info((type, value, traceback))
      File "C:\Python27\lib\site-packages\tornado\stack_context.py", line 314, in wrapped
        ret = fn(*args, **kwargs)
      File "C:\Python27\lib\site-packages\tornado\gen.py", line 149, in final_callback
        if future.result() is not None:
      File "C:\Python27\lib\site-packages\tornado\concurrent.py", line 215, in result
        raise_exc_info(self._exc_info)
      File "C:\Python27\lib\site-packages\tornado\gen.py", line 215, in wrapper
        result = func(*args, **kwargs)
      File "E:/soheil/web_site_root/ieee/all_functions/tornado-get.py", line 945, in get
        self.finish()
      File "C:\Python27\lib\site-packages\tornado\web.py", line 905, in finish
        raise RuntimeError("finish() called twice")
    RuntimeError: finish() called twice
[E 160530 19:00:53 web:1496] Uncaught exception POST /index (127.0.0.1)
    HTTPServerRequest(protocol='http', host='127.0.0.1:15001', method='POST', uri='/index', version='HTTP/1.1', remote_ip='127.0.0.1', headers={'Content-Length': '173', 'Accept-Language': 'en-US,en;q=0.5', 'Accept-Encoding': 'gzip, deflate', 'Host': '127.0.0.1:15001', 'Accept': 'text/html,application/xhtml+xml,application/xml;q=0.9,*/*;q=0.8', 'User-Agent': 'Mozilla/5.0 (Windows NT 6.1; WOW64; rv:46.0) Gecko/20100101 Firefox/46.0', 'Connection': 'keep-alive', 'Referer': 'http://127.0.0.1:15001/index', 'Content-Type': 'application/x-www-form-urlencoded'})
    Traceback (most recent call last):
      File "C:\Python27\lib\site-packages\tornado\web.py", line 1369, in _stack_context_handle_exception
        raise_exc_info((type, value, traceback))
      File "C:\Python27\lib\site-packages\tornado\stack_context.py", line 314, in wrapped
        ret = fn(*args, **kwargs)
      File "C:\Python27\lib\site-packages\tornado\gen.py", line 149, in final_callback
        if future.result() is not None:
      File "C:\Python27\lib\site-packages\tornado\concurrent.py", line 215, in result
        raise_exc_info(self._exc_info)
      File "C:\Python27\lib\site-packages\tornado\gen.py", line 215, in wrapper
        result = func(*args, **kwargs)
      File "E:/soheil/web_site_root/ieee/all_functions/tornado-get.py", line 521, in post
        result = tornado.gen.Task(self.download(details))
      File "E:/soheil/web_site_root/ieee/all_functions/tornado-get.py", line 592, in download
        water_pdfdir=root+water_pdfdir,)
      File "E:/soheil/web_site_root/ieee/all_functions\main_core.py", line 169, in valid_link
        responce= self.Find_Link(self.url,pdfdir=pdf_download_location,water_pdfdir=wat_locatton,cookies=cookies).find_link(self.pr,self.us_pss)
      File "E:/soheil/web_site_root/ieee/all_functions\find_link.py", line 262, in find_link
        res = self.new_module.LINK(url).get_pdf_link(proxy, user_pass)
      File "E:/soheil/web_site_root/ieee/all_functions/configs/Links_site/www_sciencedirect_com.py", line 3172, in get_pdf_link
        [html, cookies, links, title, form, time_diff, log_out] = twil_find_pdf_link(url)
      File "E:/soheil/web_site_root/ieee/all_functions/configs/Links_site/www_sciencedirect_com.py", line 1266, in twil_find_pdf_link
        os.remove(cookies)
    UnboundLocalError: local variable 'cookies' referenced before assignment
[E 160530 19:00:53 web:1908] 500 POST /index (127.0.0.1) 811.00ms
[I 160530 19:01:51 web:1908] 200 GET /index (127.0.0.1) 30.00ms
[E 160530 19:01:51 web:1496] Uncaught exception GET /index (127.0.0.1)
    HTTPServerRequest(protocol='http', host='127.0.0.1:15001', method='GET', uri='/index', version='HTTP/1.1', remote_ip='127.0.0.1', headers={'Connection': 'keep-alive', 'Accept-Language': 'en-US,en;q=0.5', 'Accept-Encoding': 'gzip, deflate', 'Host': '127.0.0.1:15001', 'Accept': 'text/html,application/xhtml+xml,application/xml;q=0.9,*/*;q=0.8', 'User-Agent': 'Mozilla/5.0 (Windows NT 6.1; WOW64; rv:46.0) Gecko/20100101 Firefox/46.0'})
    Traceback (most recent call last):
      File "C:\Python27\lib\site-packages\tornado\web.py", line 1369, in _stack_context_handle_exception
        raise_exc_info((type, value, traceback))
      File "C:\Python27\lib\site-packages\tornado\stack_context.py", line 314, in wrapped
        ret = fn(*args, **kwargs)
      File "C:\Python27\lib\site-packages\tornado\gen.py", line 149, in final_callback
        if future.result() is not None:
      File "C:\Python27\lib\site-packages\tornado\concurrent.py", line 215, in result
        raise_exc_info(self._exc_info)
      File "C:\Python27\lib\site-packages\tornado\gen.py", line 215, in wrapper
        result = func(*args, **kwargs)
      File "E:/soheil/web_site_root/ieee/all_functions/tornado-get.py", line 945, in get
        self.finish()
      File "C:\Python27\lib\site-packages\tornado\web.py", line 905, in finish
        raise RuntimeError("finish() called twice")
    RuntimeError: finish() called twice
[E 160530 19:01:53 web:1496] Uncaught exception POST /index (127.0.0.1)
    HTTPServerRequest(protocol='http', host='127.0.0.1:15001', method='POST', uri='/index', version='HTTP/1.1', remote_ip='127.0.0.1', headers={'Content-Length': '173', 'Accept-Language': 'en-US,en;q=0.5', 'Accept-Encoding': 'gzip, deflate', 'Host': '127.0.0.1:15001', 'Accept': 'text/html,application/xhtml+xml,application/xml;q=0.9,*/*;q=0.8', 'User-Agent': 'Mozilla/5.0 (Windows NT 6.1; WOW64; rv:46.0) Gecko/20100101 Firefox/46.0', 'Connection': 'keep-alive', 'Referer': 'http://127.0.0.1:15001/index', 'Content-Type': 'application/x-www-form-urlencoded'})
    Traceback (most recent call last):
      File "C:\Python27\lib\site-packages\tornado\web.py", line 1369, in _stack_context_handle_exception
        raise_exc_info((type, value, traceback))
      File "C:\Python27\lib\site-packages\tornado\stack_context.py", line 314, in wrapped
        ret = fn(*args, **kwargs)
      File "C:\Python27\lib\site-packages\tornado\gen.py", line 149, in final_callback
        if future.result() is not None:
      File "C:\Python27\lib\site-packages\tornado\concurrent.py", line 215, in result
        raise_exc_info(self._exc_info)
      File "C:\Python27\lib\site-packages\tornado\gen.py", line 215, in wrapper
        result = func(*args, **kwargs)
      File "E:/soheil/web_site_root/ieee/all_functions/tornado-get.py", line 521, in post
        result = tornado.gen.Task(self.download(details))
      File "E:/soheil/web_site_root/ieee/all_functions/tornado-get.py", line 592, in download
        water_pdfdir=root+water_pdfdir,)
      File "E:/soheil/web_site_root/ieee/all_functions\main_core.py", line 169, in valid_link
        responce= self.Find_Link(self.url,pdfdir=pdf_download_location,water_pdfdir=wat_locatton,cookies=cookies).find_link(self.pr,self.us_pss)
      File "E:/soheil/web_site_root/ieee/all_functions\find_link.py", line 262, in find_link
        res = self.new_module.LINK(url).get_pdf_link(proxy, user_pass)
      File "E:/soheil/web_site_root/ieee/all_functions/configs/Links_site/www_sciencedirect_com.py", line 3172, in get_pdf_link
        [html, cookies, links, title, form, time_diff, log_out] = twil_find_pdf_link(url)
      File "E:/soheil/web_site_root/ieee/all_functions/configs/Links_site/www_sciencedirect_com.py", line 1266, in twil_find_pdf_link
        os.remove(cookies)
    UnboundLocalError: local variable 'cookies' referenced before assignment
[E 160530 19:01:53 web:1908] 500 POST /index (127.0.0.1) 1277.00ms
[I 160530 19:02:26 web:1908] 200 GET /index (127.0.0.1) 24.00ms
[E 160530 19:02:26 web:1496] Uncaught exception GET /index (127.0.0.1)
    HTTPServerRequest(protocol='http', host='127.0.0.1:15001', method='GET', uri='/index', version='HTTP/1.1', remote_ip='127.0.0.1', headers={'Connection': 'keep-alive', 'Accept-Language': 'en-US,en;q=0.5', 'Accept-Encoding': 'gzip, deflate', 'Host': '127.0.0.1:15001', 'Accept': 'text/html,application/xhtml+xml,application/xml;q=0.9,*/*;q=0.8', 'User-Agent': 'Mozilla/5.0 (Windows NT 6.1; WOW64; rv:46.0) Gecko/20100101 Firefox/46.0'})
    Traceback (most recent call last):
      File "C:\Python27\lib\site-packages\tornado\web.py", line 1369, in _stack_context_handle_exception
        raise_exc_info((type, value, traceback))
      File "C:\Python27\lib\site-packages\tornado\stack_context.py", line 314, in wrapped
        ret = fn(*args, **kwargs)
      File "C:\Python27\lib\site-packages\tornado\gen.py", line 149, in final_callback
        if future.result() is not None:
      File "C:\Python27\lib\site-packages\tornado\concurrent.py", line 215, in result
        raise_exc_info(self._exc_info)
      File "C:\Python27\lib\site-packages\tornado\gen.py", line 215, in wrapper
        result = func(*args, **kwargs)
      File "E:/soheil/web_site_root/ieee/all_functions/tornado-get.py", line 945, in get
        self.finish()
      File "C:\Python27\lib\site-packages\tornado\web.py", line 905, in finish
        raise RuntimeError("finish() called twice")
    RuntimeError: finish() called twice
[E 160530 19:02:42 web:1496] Uncaught exception POST /index (127.0.0.1)
    HTTPServerRequest(protocol='http', host='127.0.0.1:15001', method='POST', uri='/index', version='HTTP/1.1', remote_ip='127.0.0.1', headers={'Content-Length': '173', 'Accept-Language': 'en-US,en;q=0.5', 'Accept-Encoding': 'gzip, deflate', 'Host': '127.0.0.1:15001', 'Accept': 'text/html,application/xhtml+xml,application/xml;q=0.9,*/*;q=0.8', 'User-Agent': 'Mozilla/5.0 (Windows NT 6.1; WOW64; rv:46.0) Gecko/20100101 Firefox/46.0', 'Connection': 'keep-alive', 'Referer': 'http://127.0.0.1:15001/index', 'Content-Type': 'application/x-www-form-urlencoded'})
    Traceback (most recent call last):
      File "C:\Python27\lib\site-packages\tornado\web.py", line 1369, in _stack_context_handle_exception
        raise_exc_info((type, value, traceback))
      File "C:\Python27\lib\site-packages\tornado\stack_context.py", line 314, in wrapped
        ret = fn(*args, **kwargs)
      File "C:\Python27\lib\site-packages\tornado\gen.py", line 149, in final_callback
        if future.result() is not None:
      File "C:\Python27\lib\site-packages\tornado\concurrent.py", line 215, in result
        raise_exc_info(self._exc_info)
      File "C:\Python27\lib\site-packages\tornado\gen.py", line 215, in wrapper
        result = func(*args, **kwargs)
      File "E:/soheil/web_site_root/ieee/all_functions/tornado-get.py", line 521, in post
        result = tornado.gen.Task(self.download(details))
      File "E:/soheil/web_site_root/ieee/all_functions/tornado-get.py", line 592, in download
        water_pdfdir=root+water_pdfdir,)
      File "E:/soheil/web_site_root/ieee/all_functions\main_core.py", line 169, in valid_link
        responce= self.Find_Link(self.url,pdfdir=pdf_download_location,water_pdfdir=wat_locatton,cookies=cookies).find_link(self.pr,self.us_pss)
      File "E:/soheil/web_site_root/ieee/all_functions\find_link.py", line 262, in find_link
        res = self.new_module.LINK(url).get_pdf_link(proxy, user_pass)
      File "E:/soheil/web_site_root/ieee/all_functions/configs/Links_site/www_sciencedirect_com.py", line 3172, in get_pdf_link
        [html, cookies, links, title, form, time_diff, log_out] = twil_find_pdf_link(url)
      File "E:/soheil/web_site_root/ieee/all_functions/configs/Links_site/www_sciencedirect_com.py", line 1266, in twil_find_pdf_link
        os.remove(cookies)
    UnboundLocalError: local variable 'cookies' referenced before assignment
[E 160530 19:02:42 web:1908] 500 POST /index (127.0.0.1) 12303.00ms
[I 160530 19:03:23 web:1908] 200 GET /index (127.0.0.1) 30.00ms
[E 160530 19:03:23 web:1496] Uncaught exception GET /index (127.0.0.1)
    HTTPServerRequest(protocol='http', host='127.0.0.1:15001', method='GET', uri='/index', version='HTTP/1.1', remote_ip='127.0.0.1', headers={'Connection': 'keep-alive', 'Accept-Language': 'en-US,en;q=0.5', 'Accept-Encoding': 'gzip, deflate', 'Host': '127.0.0.1:15001', 'Accept': 'text/html,application/xhtml+xml,application/xml;q=0.9,*/*;q=0.8', 'User-Agent': 'Mozilla/5.0 (Windows NT 6.1; WOW64; rv:46.0) Gecko/20100101 Firefox/46.0'})
    Traceback (most recent call last):
      File "C:\Python27\lib\site-packages\tornado\web.py", line 1369, in _stack_context_handle_exception
        raise_exc_info((type, value, traceback))
      File "C:\Python27\lib\site-packages\tornado\stack_context.py", line 314, in wrapped
        ret = fn(*args, **kwargs)
      File "C:\Python27\lib\site-packages\tornado\gen.py", line 149, in final_callback
        if future.result() is not None:
      File "C:\Python27\lib\site-packages\tornado\concurrent.py", line 215, in result
        raise_exc_info(self._exc_info)
      File "C:\Python27\lib\site-packages\tornado\gen.py", line 215, in wrapper
        result = func(*args, **kwargs)
      File "E:/soheil/web_site_root/ieee/all_functions/tornado-get.py", line 945, in get
        self.finish()
      File "C:\Python27\lib\site-packages\tornado\web.py", line 905, in finish
        raise RuntimeError("finish() called twice")
    RuntimeError: finish() called twice
[E 160530 19:03:49 web:1496] Uncaught exception POST /index (127.0.0.1)
    HTTPServerRequest(protocol='http', host='127.0.0.1:15001', method='POST', uri='/index', version='HTTP/1.1', remote_ip='127.0.0.1', headers={'Content-Length': '173', 'Accept-Language': 'en-US,en;q=0.5', 'Accept-Encoding': 'gzip, deflate', 'Host': '127.0.0.1:15001', 'Accept': 'text/html,application/xhtml+xml,application/xml;q=0.9,*/*;q=0.8', 'User-Agent': 'Mozilla/5.0 (Windows NT 6.1; WOW64; rv:46.0) Gecko/20100101 Firefox/46.0', 'Connection': 'keep-alive', 'Referer': 'http://127.0.0.1:15001/index', 'Content-Type': 'application/x-www-form-urlencoded'})
    Traceback (most recent call last):
      File "C:\Python27\lib\site-packages\tornado\web.py", line 1369, in _stack_context_handle_exception
        raise_exc_info((type, value, traceback))
      File "C:\Python27\lib\site-packages\tornado\stack_context.py", line 314, in wrapped
        ret = fn(*args, **kwargs)
      File "C:\Python27\lib\site-packages\tornado\gen.py", line 149, in final_callback
        if future.result() is not None:
      File "C:\Python27\lib\site-packages\tornado\concurrent.py", line 215, in result
        raise_exc_info(self._exc_info)
      File "C:\Python27\lib\site-packages\tornado\gen.py", line 215, in wrapper
        result = func(*args, **kwargs)
      File "E:/soheil/web_site_root/ieee/all_functions/tornado-get.py", line 521, in post
        result = tornado.gen.Task(self.download(details))
      File "E:/soheil/web_site_root/ieee/all_functions/tornado-get.py", line 592, in download
        water_pdfdir=root+water_pdfdir,)
      File "E:/soheil/web_site_root/ieee/all_functions\main_core.py", line 169, in valid_link
        responce= self.Find_Link(self.url,pdfdir=pdf_download_location,water_pdfdir=wat_locatton,cookies=cookies).find_link(self.pr,self.us_pss)
      File "E:/soheil/web_site_root/ieee/all_functions\find_link.py", line 262, in find_link
        res = self.new_module.LINK(url).get_pdf_link(proxy, user_pass)
      File "E:/soheil/web_site_root/ieee/all_functions/configs/Links_site/www_sciencedirect_com.py", line 3172, in get_pdf_link
        [html, cookies, links, title, form, time_diff, log_out] = twil_find_pdf_link(url)
      File "E:/soheil/web_site_root/ieee/all_functions/configs/Links_site/www_sciencedirect_com.py", line 1266, in twil_find_pdf_link
        os.remove(cookies)
    WindowsError: [Error 3] The system cannot find the path specified: ''
[E 160530 19:03:49 web:1908] 500 POST /index (127.0.0.1) 10636.00ms
[I 160530 19:05:29 web:1908] 200 GET /index (127.0.0.1) 23.00ms
[E 160530 19:05:29 web:1496] Uncaught exception GET /index (127.0.0.1)
    HTTPServerRequest(protocol='http', host='127.0.0.1:15001', method='GET', uri='/index', version='HTTP/1.1', remote_ip='127.0.0.1', headers={'Connection': 'keep-alive', 'Accept-Language': 'en-US,en;q=0.5', 'Accept-Encoding': 'gzip, deflate', 'Host': '127.0.0.1:15001', 'Accept': 'text/html,application/xhtml+xml,application/xml;q=0.9,*/*;q=0.8', 'User-Agent': 'Mozilla/5.0 (Windows NT 6.1; WOW64; rv:46.0) Gecko/20100101 Firefox/46.0'})
    Traceback (most recent call last):
      File "C:\Python27\lib\site-packages\tornado\web.py", line 1369, in _stack_context_handle_exception
        raise_exc_info((type, value, traceback))
      File "C:\Python27\lib\site-packages\tornado\stack_context.py", line 314, in wrapped
        ret = fn(*args, **kwargs)
      File "C:\Python27\lib\site-packages\tornado\gen.py", line 149, in final_callback
        if future.result() is not None:
      File "C:\Python27\lib\site-packages\tornado\concurrent.py", line 215, in result
        raise_exc_info(self._exc_info)
      File "C:\Python27\lib\site-packages\tornado\gen.py", line 215, in wrapper
        result = func(*args, **kwargs)
      File "E:/soheil/web_site_root/ieee/all_functions/tornado-get.py", line 945, in get
        self.finish()
      File "C:\Python27\lib\site-packages\tornado\web.py", line 905, in finish
        raise RuntimeError("finish() called twice")
    RuntimeError: finish() called twice
[E 160530 19:07:04 web:1496] Uncaught exception POST /index (127.0.0.1)
    HTTPServerRequest(protocol='http', host='127.0.0.1:15001', method='POST', uri='/index', version='HTTP/1.1', remote_ip='127.0.0.1', headers={'Content-Length': '173', 'Accept-Language': 'en-US,en;q=0.5', 'Accept-Encoding': 'gzip, deflate', 'Host': '127.0.0.1:15001', 'Accept': 'text/html,application/xhtml+xml,application/xml;q=0.9,*/*;q=0.8', 'User-Agent': 'Mozilla/5.0 (Windows NT 6.1; WOW64; rv:46.0) Gecko/20100101 Firefox/46.0', 'Connection': 'keep-alive', 'Referer': 'http://127.0.0.1:15001/index', 'Content-Type': 'application/x-www-form-urlencoded'})
    Traceback (most recent call last):
      File "C:\Python27\lib\site-packages\tornado\web.py", line 1369, in _stack_context_handle_exception
        raise_exc_info((type, value, traceback))
      File "C:\Python27\lib\site-packages\tornado\stack_context.py", line 314, in wrapped
        ret = fn(*args, **kwargs)
      File "C:\Python27\lib\site-packages\tornado\gen.py", line 149, in final_callback
        if future.result() is not None:
      File "C:\Python27\lib\site-packages\tornado\concurrent.py", line 215, in result
        raise_exc_info(self._exc_info)
      File "C:\Python27\lib\site-packages\tornado\gen.py", line 215, in wrapper
        result = func(*args, **kwargs)
      File "E:/soheil/web_site_root/ieee/all_functions/tornado-get.py", line 521, in post
        result = tornado.gen.Task(self.download(details))
      File "E:/soheil/web_site_root/ieee/all_functions/tornado-get.py", line 666, in download
        proxy=proxy,user_pass=user_pass,cookies=cookies,log_out=log_out,ftp_upload=ftp_upload,html=html)
      File "E:/soheil/web_site_root/ieee/all_functions\main_core.py", line 398, in download_link
        pdf_dw_dir, pdf_dw_Wr_dir = PDF_File(url,pdf_download_location,wat_locatton).finall_file_saving(html, file_name,pdf_download_location,no_watermarker=0)
      File "E:/soheil/web_site_root/ieee/all_functions\save_source.py", line 328, in finall_file_saving
        self.pdf_watermark_fast(localName.pdf_Folder_filename, localName.W_pdf_Folder_filename,url_wtm=url_watermark)
      File "E:/soheil/web_site_root/ieee/all_functions\save_source.py", line 174, in pdf_watermark_fast
        watermark1 = PdfFileReader(file(wt1, 'rb'))
    IOError: [Errno 2] No such file or directory: 'E:/soheil/web_site_root/ieee/all_functions/static/watermarker_fast.pdf'
[E 160530 19:07:04 web:1908] 500 POST /index (127.0.0.1) 93107.00ms
[I 160530 19:07:08 web:1908] 200 GET /index (127.0.0.1) 12.00ms
[E 160530 19:07:08 web:1496] Uncaught exception GET /index (127.0.0.1)
    HTTPServerRequest(protocol='http', host='127.0.0.1:15001', method='GET', uri='/index', version='HTTP/1.1', remote_ip='127.0.0.1', headers={'Connection': 'keep-alive', 'Accept-Language': 'en-US,en;q=0.5', 'Accept-Encoding': 'gzip, deflate', 'Host': '127.0.0.1:15001', 'Accept': 'text/html,application/xhtml+xml,application/xml;q=0.9,*/*;q=0.8', 'User-Agent': 'Mozilla/5.0 (Windows NT 6.1; WOW64; rv:46.0) Gecko/20100101 Firefox/46.0'})
    Traceback (most recent call last):
      File "C:\Python27\lib\site-packages\tornado\web.py", line 1369, in _stack_context_handle_exception
        raise_exc_info((type, value, traceback))
      File "C:\Python27\lib\site-packages\tornado\stack_context.py", line 314, in wrapped
        ret = fn(*args, **kwargs)
      File "C:\Python27\lib\site-packages\tornado\gen.py", line 149, in final_callback
        if future.result() is not None:
      File "C:\Python27\lib\site-packages\tornado\concurrent.py", line 215, in result
        raise_exc_info(self._exc_info)
      File "C:\Python27\lib\site-packages\tornado\gen.py", line 215, in wrapper
        result = func(*args, **kwargs)
      File "E:/soheil/web_site_root/ieee/all_functions/tornado-get.py", line 945, in get
        self.finish()
      File "C:\Python27\lib\site-packages\tornado\web.py", line 905, in finish
        raise RuntimeError("finish() called twice")
    RuntimeError: finish() called twice
[E 160530 19:12:23 web:1496] Uncaught exception POST /index (127.0.0.1)
    HTTPServerRequest(protocol='http', host='127.0.0.1:15001', method='POST', uri='/index', version='HTTP/1.1', remote_ip='127.0.0.1', headers={'Content-Length': '173', 'Accept-Language': 'en-US,en;q=0.5', 'Accept-Encoding': 'gzip, deflate', 'Host': '127.0.0.1:15001', 'Accept': 'text/html,application/xhtml+xml,application/xml;q=0.9,*/*;q=0.8', 'User-Agent': 'Mozilla/5.0 (Windows NT 6.1; WOW64; rv:46.0) Gecko/20100101 Firefox/46.0', 'Connection': 'keep-alive', 'Referer': 'http://127.0.0.1:15001/index', 'Content-Type': 'application/x-www-form-urlencoded'})
    Traceback (most recent call last):
      File "C:\Python27\lib\site-packages\tornado\web.py", line 1369, in _stack_context_handle_exception
        raise_exc_info((type, value, traceback))
      File "C:\Python27\lib\site-packages\tornado\stack_context.py", line 314, in wrapped
        ret = fn(*args, **kwargs)
      File "C:\Python27\lib\site-packages\tornado\gen.py", line 149, in final_callback
        if future.result() is not None:
      File "C:\Python27\lib\site-packages\tornado\concurrent.py", line 215, in result
        raise_exc_info(self._exc_info)
      File "C:\Python27\lib\site-packages\tornado\gen.py", line 215, in wrapper
        result = func(*args, **kwargs)
      File "E:/soheil/web_site_root/ieee/all_functions/tornado-get.py", line 521, in post
        result = tornado.gen.Task(self.download(details))
      File "E:/soheil/web_site_root/ieee/all_functions/tornado-get.py", line 666, in download
        proxy=proxy,user_pass=user_pass,cookies=cookies,log_out=log_out,ftp_upload=ftp_upload,html=html)
      File "E:/soheil/web_site_root/ieee/all_functions\main_core.py", line 398, in download_link
        pdf_dw_dir, pdf_dw_Wr_dir = PDF_File(url,pdf_download_location,wat_locatton).finall_file_saving(html, file_name,pdf_download_location,no_watermarker=0)
      File "E:/soheil/web_site_root/ieee/all_functions\save_source.py", line 332, in finall_file_saving
        self.pdf_watermark_fast(localName.pdf_Folder_filename, localName.W_pdf_Folder_filename,url_wtm=url_watermark)
      File "E:/soheil/web_site_root/ieee/all_functions\save_source.py", line 181, in pdf_watermark_fast
        watter_marker.op_w_input(pathname, wt1, Wm_f)
      File "E:/soheil/web_site_root/ieee/all_functions\watter_marker.py", line 114, in op_w_input
        PdfWriter().addpages([fixpage(x,watermark) for x in pages]).write(outfn0)
      File "E:/soheil/web_site_root/ieee/all_functions\watter_marker.py", line 38, in fixpage
        xobjdict[watermark_name] = watermark
      File "C:\Python27\lib\site-packages\pdfrw\objects\pdfdict.py", line 108, in __setitem__
        raise PdfParseError('Dict key %s is not a PdfName' % repr(name))
    PdfParseError: Dict key '/Watermark.0' is not a PdfName
[E 160530 19:12:23 web:1908] 500 POST /index (127.0.0.1) 40901.00ms
[I 160530 19:12:25 web:1908] 200 GET /index (127.0.0.1) 25.00ms
[E 160530 19:12:25 web:1496] Uncaught exception GET /index (127.0.0.1)
    HTTPServerRequest(protocol='http', host='127.0.0.1:15001', method='GET', uri='/index', version='HTTP/1.1', remote_ip='127.0.0.1', headers={'Connection': 'keep-alive', 'Accept-Language': 'en-US,en;q=0.5', 'Accept-Encoding': 'gzip, deflate', 'Host': '127.0.0.1:15001', 'Accept': 'text/html,application/xhtml+xml,application/xml;q=0.9,*/*;q=0.8', 'User-Agent': 'Mozilla/5.0 (Windows NT 6.1; WOW64; rv:46.0) Gecko/20100101 Firefox/46.0'})
    Traceback (most recent call last):
      File "C:\Python27\lib\site-packages\tornado\web.py", line 1369, in _stack_context_handle_exception
        raise_exc_info((type, value, traceback))
      File "C:\Python27\lib\site-packages\tornado\stack_context.py", line 314, in wrapped
        ret = fn(*args, **kwargs)
      File "C:\Python27\lib\site-packages\tornado\gen.py", line 149, in final_callback
        if future.result() is not None:
      File "C:\Python27\lib\site-packages\tornado\concurrent.py", line 215, in result
        raise_exc_info(self._exc_info)
      File "C:\Python27\lib\site-packages\tornado\gen.py", line 215, in wrapper
        result = func(*args, **kwargs)
      File "E:/soheil/web_site_root/ieee/all_functions/tornado-get.py", line 945, in get
        self.finish()
      File "C:\Python27\lib\site-packages\tornado\web.py", line 905, in finish
        raise RuntimeError("finish() called twice")
    RuntimeError: finish() called twice
[E 160530 19:13:40 web:1496] Uncaught exception POST /index (127.0.0.1)
    HTTPServerRequest(protocol='http', host='127.0.0.1:15001', method='POST', uri='/index', version='HTTP/1.1', remote_ip='127.0.0.1', headers={'Content-Length': '173', 'Accept-Language': 'en-US,en;q=0.5', 'Accept-Encoding': 'gzip, deflate', 'Host': '127.0.0.1:15001', 'Accept': 'text/html,application/xhtml+xml,application/xml;q=0.9,*/*;q=0.8', 'User-Agent': 'Mozilla/5.0 (Windows NT 6.1; WOW64; rv:46.0) Gecko/20100101 Firefox/46.0', 'Connection': 'keep-alive', 'Referer': 'http://127.0.0.1:15001/index', 'Content-Type': 'application/x-www-form-urlencoded'})
    Traceback (most recent call last):
      File "C:\Python27\lib\site-packages\tornado\web.py", line 1369, in _stack_context_handle_exception
        raise_exc_info((type, value, traceback))
      File "C:\Python27\lib\site-packages\tornado\stack_context.py", line 314, in wrapped
        ret = fn(*args, **kwargs)
      File "C:\Python27\lib\site-packages\tornado\gen.py", line 149, in final_callback
        if future.result() is not None:
      File "C:\Python27\lib\site-packages\tornado\concurrent.py", line 215, in result
        raise_exc_info(self._exc_info)
      File "C:\Python27\lib\site-packages\tornado\gen.py", line 215, in wrapper
        result = func(*args, **kwargs)
      File "E:/soheil/web_site_root/ieee/all_functions/tornado-get.py", line 521, in post
        result = tornado.gen.Task(self.download(details))
      File "E:/soheil/web_site_root/ieee/all_functions/tornado-get.py", line 666, in download
        proxy=proxy,user_pass=user_pass,cookies=cookies,log_out=log_out,ftp_upload=ftp_upload,html=html)
      File "E:/soheil/web_site_root/ieee/all_functions\main_core.py", line 398, in download_link
        pdf_dw_dir, pdf_dw_Wr_dir = PDF_File(url,pdf_download_location,wat_locatton).finall_file_saving(html, file_name,pdf_download_location,no_watermarker=0)
      File "E:/soheil/web_site_root/ieee/all_functions\save_source.py", line 332, in finall_file_saving
        self.pdf_watermark_fast(localName.pdf_Folder_filename, localName.W_pdf_Folder_filename,url_wtm=url_watermark)
      File "E:/soheil/web_site_root/ieee/all_functions\save_source.py", line 181, in pdf_watermark_fast
        watter_marker.op_w_input(pathname, wt1, Wm_f)
      File "E:/soheil/web_site_root/ieee/all_functions\watter_marker.py", line 114, in op_w_input
        PdfWriter().addpages([fixpage(x,watermark) for x in pages]).write(outfn0)
      File "E:/soheil/web_site_root/ieee/all_functions\watter_marker.py", line 38, in fixpage
        xobjdict[watermark_name] = watermark
      File "C:\Python27\lib\site-packages\pdfrw\objects\pdfdict.py", line 108, in __setitem__
        raise PdfParseError('Dict key %s is not a PdfName' % repr(name))
    PdfParseError: Dict key '/Watermark.0' is not a PdfName
[E 160530 19:13:40 web:1908] 500 POST /index (127.0.0.1) 61781.00ms
[I 160530 19:13:43 web:1908] 200 GET /index (127.0.0.1) 17.00ms
[E 160530 19:13:43 web:1496] Uncaught exception GET /index (127.0.0.1)
    HTTPServerRequest(protocol='http', host='127.0.0.1:15001', method='GET', uri='/index', version='HTTP/1.1', remote_ip='127.0.0.1', headers={'Connection': 'keep-alive', 'Accept-Language': 'en-US,en;q=0.5', 'Accept-Encoding': 'gzip, deflate', 'Host': '127.0.0.1:15001', 'Accept': 'text/html,application/xhtml+xml,application/xml;q=0.9,*/*;q=0.8', 'User-Agent': 'Mozilla/5.0 (Windows NT 6.1; WOW64; rv:46.0) Gecko/20100101 Firefox/46.0'})
    Traceback (most recent call last):
      File "C:\Python27\lib\site-packages\tornado\web.py", line 1369, in _stack_context_handle_exception
        raise_exc_info((type, value, traceback))
      File "C:\Python27\lib\site-packages\tornado\stack_context.py", line 314, in wrapped
        ret = fn(*args, **kwargs)
      File "C:\Python27\lib\site-packages\tornado\gen.py", line 149, in final_callback
        if future.result() is not None:
      File "C:\Python27\lib\site-packages\tornado\concurrent.py", line 215, in result
        raise_exc_info(self._exc_info)
      File "C:\Python27\lib\site-packages\tornado\gen.py", line 215, in wrapper
        result = func(*args, **kwargs)
      File "E:/soheil/web_site_root/ieee/all_functions/tornado-get.py", line 945, in get
        self.finish()
      File "C:\Python27\lib\site-packages\tornado\web.py", line 905, in finish
        raise RuntimeError("finish() called twice")
    RuntimeError: finish() called twice
[E 160530 19:15:34 web:1496] Uncaught exception POST /index (127.0.0.1)
    HTTPServerRequest(protocol='http', host='127.0.0.1:15001', method='POST', uri='/index', version='HTTP/1.1', remote_ip='127.0.0.1', headers={'Content-Length': '173', 'Accept-Language': 'en-US,en;q=0.5', 'Accept-Encoding': 'gzip, deflate', 'Host': '127.0.0.1:15001', 'Accept': 'text/html,application/xhtml+xml,application/xml;q=0.9,*/*;q=0.8', 'User-Agent': 'Mozilla/5.0 (Windows NT 6.1; WOW64; rv:46.0) Gecko/20100101 Firefox/46.0', 'Connection': 'keep-alive', 'Referer': 'http://127.0.0.1:15001/index', 'Content-Type': 'application/x-www-form-urlencoded'})
    Traceback (most recent call last):
      File "C:\Python27\lib\site-packages\tornado\web.py", line 1369, in _stack_context_handle_exception
        raise_exc_info((type, value, traceback))
      File "C:\Python27\lib\site-packages\tornado\stack_context.py", line 314, in wrapped
        ret = fn(*args, **kwargs)
      File "C:\Python27\lib\site-packages\tornado\gen.py", line 149, in final_callback
        if future.result() is not None:
      File "C:\Python27\lib\site-packages\tornado\concurrent.py", line 215, in result
        raise_exc_info(self._exc_info)
      File "C:\Python27\lib\site-packages\tornado\gen.py", line 215, in wrapper
        result = func(*args, **kwargs)
      File "E:/soheil/web_site_root/ieee/all_functions/tornado-get.py", line 521, in post
        result = tornado.gen.Task(self.download(details))
      File "E:/soheil/web_site_root/ieee/all_functions/tornado-get.py", line 666, in download
        proxy=proxy,user_pass=user_pass,cookies=cookies,log_out=log_out,ftp_upload=ftp_upload,html=html)
      File "E:/soheil/web_site_root/ieee/all_functions\main_core.py", line 398, in download_link
        pdf_dw_dir, pdf_dw_Wr_dir = PDF_File(url,pdf_download_location,wat_locatton).finall_file_saving(html, file_name,pdf_download_location,no_watermarker=0)
      File "E:/soheil/web_site_root/ieee/all_functions\save_source.py", line 332, in finall_file_saving
        self.pdf_watermark_fast(localName.pdf_Folder_filename, localName.W_pdf_Folder_filename,url_wtm=url_watermark)
      File "E:/soheil/web_site_root/ieee/all_functions\save_source.py", line 181, in pdf_watermark_fast
        watter_marker.op_w_input(pathname, wt1, Wm_f)
      File "E:/soheil/web_site_root/ieee/all_functions\watter_marker.py", line 114, in op_w_input
        PdfWriter().addpages([fixpage(x,watermark) for x in pages]).write(outfn0)
      File "E:/soheil/web_site_root/ieee/all_functions\watter_marker.py", line 38, in fixpage
        xobjdict[watermark_name] = watermark
      File "C:\Python27\lib\site-packages\pdfrw\objects\pdfdict.py", line 108, in __setitem__
        raise PdfParseError('Dict key %s is not a PdfName' % repr(name))
    PdfParseError: Dict key '/Watermark.0' is not a PdfName
[E 160530 19:15:34 web:1908] 500 POST /index (127.0.0.1) 110457.00ms
[I 160530 19:15:39 web:1908] 200 GET /index (127.0.0.1) 7.00ms
[E 160530 19:15:39 web:1496] Uncaught exception GET /index (127.0.0.1)
    HTTPServerRequest(protocol='http', host='127.0.0.1:15001', method='GET', uri='/index', version='HTTP/1.1', remote_ip='127.0.0.1', headers={'Connection': 'keep-alive', 'Accept-Language': 'en-US,en;q=0.5', 'Accept-Encoding': 'gzip, deflate', 'Host': '127.0.0.1:15001', 'Accept': 'text/html,application/xhtml+xml,application/xml;q=0.9,*/*;q=0.8', 'User-Agent': 'Mozilla/5.0 (Windows NT 6.1; WOW64; rv:46.0) Gecko/20100101 Firefox/46.0'})
    Traceback (most recent call last):
      File "C:\Python27\lib\site-packages\tornado\web.py", line 1369, in _stack_context_handle_exception
        raise_exc_info((type, value, traceback))
      File "C:\Python27\lib\site-packages\tornado\stack_context.py", line 314, in wrapped
        ret = fn(*args, **kwargs)
      File "C:\Python27\lib\site-packages\tornado\gen.py", line 149, in final_callback
        if future.result() is not None:
      File "C:\Python27\lib\site-packages\tornado\concurrent.py", line 215, in result
        raise_exc_info(self._exc_info)
      File "C:\Python27\lib\site-packages\tornado\gen.py", line 215, in wrapper
        result = func(*args, **kwargs)
      File "E:/soheil/web_site_root/ieee/all_functions/tornado-get.py", line 945, in get
        self.finish()
      File "C:\Python27\lib\site-packages\tornado\web.py", line 905, in finish
        raise RuntimeError("finish() called twice")
    RuntimeError: finish() called twice
[E 160530 19:17:22 web:1496] Uncaught exception POST /index (127.0.0.1)
    HTTPServerRequest(protocol='http', host='127.0.0.1:15001', method='POST', uri='/index', version='HTTP/1.1', remote_ip='127.0.0.1', headers={'Content-Length': '173', 'Accept-Language': 'en-US,en;q=0.5', 'Accept-Encoding': 'gzip, deflate', 'Host': '127.0.0.1:15001', 'Accept': 'text/html,application/xhtml+xml,application/xml;q=0.9,*/*;q=0.8', 'User-Agent': 'Mozilla/5.0 (Windows NT 6.1; WOW64; rv:46.0) Gecko/20100101 Firefox/46.0', 'Connection': 'keep-alive', 'Referer': 'http://127.0.0.1:15001/index', 'Content-Type': 'application/x-www-form-urlencoded'})
    Traceback (most recent call last):
      File "C:\Python27\lib\site-packages\tornado\web.py", line 1369, in _stack_context_handle_exception
        raise_exc_info((type, value, traceback))
      File "C:\Python27\lib\site-packages\tornado\stack_context.py", line 314, in wrapped
        ret = fn(*args, **kwargs)
      File "C:\Python27\lib\site-packages\tornado\gen.py", line 149, in final_callback
        if future.result() is not None:
      File "C:\Python27\lib\site-packages\tornado\concurrent.py", line 215, in result
        raise_exc_info(self._exc_info)
      File "C:\Python27\lib\site-packages\tornado\gen.py", line 215, in wrapper
        result = func(*args, **kwargs)
      File "E:/soheil/web_site_root/ieee/all_functions/tornado-get.py", line 521, in post
        result = tornado.gen.Task(self.download(details))
      File "E:/soheil/web_site_root/ieee/all_functions/tornado-get.py", line 666, in download
        proxy=proxy,user_pass=user_pass,cookies=cookies,log_out=log_out,ftp_upload=ftp_upload,html=html)
      File "E:/soheil/web_site_root/ieee/all_functions\main_core.py", line 398, in download_link
        pdf_dw_dir, pdf_dw_Wr_dir = PDF_File(url,pdf_download_location,wat_locatton).finall_file_saving(html, file_name,pdf_download_location,no_watermarker=0)
      File "E:/soheil/web_site_root/ieee/all_functions\save_source.py", line 332, in finall_file_saving
        self.pdf_watermark_fast(localName.pdf_Folder_filename, localName.W_pdf_Folder_filename,url_wtm=url_watermark)
      File "E:/soheil/web_site_root/ieee/all_functions\save_source.py", line 181, in pdf_watermark_fast
        watter_marker.op_w_input(pathname, wt1, Wm_f)
      File "E:/soheil/web_site_root/ieee/all_functions\watter_marker.py", line 114, in op_w_input
        PdfWriter().addpages([fixpage(x,watermark) for x in pages]).write(outfn0)
      File "E:/soheil/web_site_root/ieee/all_functions\watter_marker.py", line 38, in fixpage
        xobjdict[watermark_name] = watermark
      File "C:\Python27\lib\site-packages\pdfrw\objects\pdfdict.py", line 108, in __setitem__
        raise PdfParseError('Dict key %s is not a PdfName' % repr(name))
    PdfParseError: Dict key '/Watermark.0' is not a PdfName
[E 160530 19:17:22 web:1908] 500 POST /index (127.0.0.1) 101993.00ms
[I 160530 19:17:25 web:1908] 200 GET /index (127.0.0.1) 26.00ms
[E 160530 19:17:25 web:1496] Uncaught exception GET /index (127.0.0.1)
    HTTPServerRequest(protocol='http', host='127.0.0.1:15001', method='GET', uri='/index', version='HTTP/1.1', remote_ip='127.0.0.1', headers={'Connection': 'keep-alive', 'Accept-Language': 'en-US,en;q=0.5', 'Accept-Encoding': 'gzip, deflate', 'Host': '127.0.0.1:15001', 'Accept': 'text/html,application/xhtml+xml,application/xml;q=0.9,*/*;q=0.8', 'User-Agent': 'Mozilla/5.0 (Windows NT 6.1; WOW64; rv:46.0) Gecko/20100101 Firefox/46.0'})
    Traceback (most recent call last):
      File "C:\Python27\lib\site-packages\tornado\web.py", line 1369, in _stack_context_handle_exception
        raise_exc_info((type, value, traceback))
      File "C:\Python27\lib\site-packages\tornado\stack_context.py", line 314, in wrapped
        ret = fn(*args, **kwargs)
      File "C:\Python27\lib\site-packages\tornado\gen.py", line 149, in final_callback
        if future.result() is not None:
      File "C:\Python27\lib\site-packages\tornado\concurrent.py", line 215, in result
        raise_exc_info(self._exc_info)
      File "C:\Python27\lib\site-packages\tornado\gen.py", line 215, in wrapper
        result = func(*args, **kwargs)
      File "E:/soheil/web_site_root/ieee/all_functions/tornado-get.py", line 945, in get
        self.finish()
      File "C:\Python27\lib\site-packages\tornado\web.py", line 905, in finish
        raise RuntimeError("finish() called twice")
    RuntimeError: finish() called twice
[I 160530 19:28:45 web:1908] 200 POST /index (127.0.0.1) 88717.00ms
[W 160530 19:28:45 web:1908] 404 GET /htmls/simple_cursor.css (127.0.0.1) 9.00ms
[I 160530 19:42:10 web:1908] 200 GET /index (127.0.0.1) 31.00ms
[E 160530 19:42:10 web:1496] Uncaught exception GET /index (127.0.0.1)
    HTTPServerRequest(protocol='http', host='127.0.0.1:15001', method='GET', uri='/index', version='HTTP/1.1', remote_ip='127.0.0.1', headers={'Connection': 'keep-alive', 'Accept-Language': 'en-US,en;q=0.5', 'Accept-Encoding': 'gzip, deflate', 'Host': '127.0.0.1:15001', 'Accept': 'text/html,application/xhtml+xml,application/xml;q=0.9,*/*;q=0.8', 'User-Agent': 'Mozilla/5.0 (Windows NT 6.1; WOW64; rv:46.0) Gecko/20100101 Firefox/46.0'})
    Traceback (most recent call last):
      File "C:\Python27\lib\site-packages\tornado\web.py", line 1369, in _stack_context_handle_exception
        raise_exc_info((type, value, traceback))
      File "C:\Python27\lib\site-packages\tornado\stack_context.py", line 314, in wrapped
        ret = fn(*args, **kwargs)
      File "C:\Python27\lib\site-packages\tornado\gen.py", line 149, in final_callback
        if future.result() is not None:
      File "C:\Python27\lib\site-packages\tornado\concurrent.py", line 215, in result
        raise_exc_info(self._exc_info)
      File "C:\Python27\lib\site-packages\tornado\gen.py", line 215, in wrapper
        result = func(*args, **kwargs)
      File "E:/soheil/web_site_root/ieee/all_functions/tornado-get.py", line 945, in get
        self.finish()
      File "C:\Python27\lib\site-packages\tornado\web.py", line 905, in finish
        raise RuntimeError("finish() called twice")
    RuntimeError: finish() called twice
[I 160530 19:44:06 web:1908] 200 POST /index (127.0.0.1) 113988.00ms
[W 160530 19:44:06 web:1908] 404 GET /htmls/simple_cursor.css (127.0.0.1) 7.00ms
[I 160530 19:45:17 web:1908] 200 GET /index (127.0.0.1) 18.00ms
[E 160530 19:45:17 web:1496] Uncaught exception GET /index (127.0.0.1)
    HTTPServerRequest(protocol='http', host='127.0.0.1:15001', method='GET', uri='/index', version='HTTP/1.1', remote_ip='127.0.0.1', headers={'Connection': 'keep-alive', 'Accept-Language': 'en-US,en;q=0.5', 'Accept-Encoding': 'gzip, deflate', 'Host': '127.0.0.1:15001', 'Accept': 'text/html,application/xhtml+xml,application/xml;q=0.9,*/*;q=0.8', 'User-Agent': 'Mozilla/5.0 (Windows NT 6.1; WOW64; rv:46.0) Gecko/20100101 Firefox/46.0'})
    Traceback (most recent call last):
      File "C:\Python27\lib\site-packages\tornado\web.py", line 1369, in _stack_context_handle_exception
        raise_exc_info((type, value, traceback))
      File "C:\Python27\lib\site-packages\tornado\stack_context.py", line 314, in wrapped
        ret = fn(*args, **kwargs)
      File "C:\Python27\lib\site-packages\tornado\gen.py", line 149, in final_callback
        if future.result() is not None:
      File "C:\Python27\lib\site-packages\tornado\concurrent.py", line 215, in result
        raise_exc_info(self._exc_info)
      File "C:\Python27\lib\site-packages\tornado\gen.py", line 215, in wrapper
        result = func(*args, **kwargs)
      File "E:/soheil/web_site_root/ieee/all_functions/tornado-get.py", line 945, in get
        self.finish()
      File "C:\Python27\lib\site-packages\tornado\web.py", line 905, in finish
        raise RuntimeError("finish() called twice")
    RuntimeError: finish() called twice
[I 160530 19:45:21 web:1908] 304 GET /index (127.0.0.1) 8.00ms
[E 160530 19:45:21 web:1496] Uncaught exception GET /index (127.0.0.1)
    HTTPServerRequest(protocol='http', host='127.0.0.1:15001', method='GET', uri='/index', version='HTTP/1.1', remote_ip='127.0.0.1', headers={'Accept-Language': 'en-US,en;q=0.5', 'Accept-Encoding': 'gzip, deflate', 'Host': '127.0.0.1:15001', 'Accept': 'text/html,application/xhtml+xml,application/xml;q=0.9,*/*;q=0.8', 'User-Agent': 'Mozilla/5.0 (Windows NT 6.1; WOW64; rv:46.0) Gecko/20100101 Firefox/46.0', 'Connection': 'keep-alive', 'Cache-Control': 'max-age=0', 'If-None-Match': '"ac3838f960162e71ed9e305cb3d15695eead5282"'})
    Traceback (most recent call last):
      File "C:\Python27\lib\site-packages\tornado\web.py", line 1369, in _stack_context_handle_exception
        raise_exc_info((type, value, traceback))
      File "C:\Python27\lib\site-packages\tornado\stack_context.py", line 314, in wrapped
        ret = fn(*args, **kwargs)
      File "C:\Python27\lib\site-packages\tornado\gen.py", line 149, in final_callback
        if future.result() is not None:
      File "C:\Python27\lib\site-packages\tornado\concurrent.py", line 215, in result
        raise_exc_info(self._exc_info)
      File "C:\Python27\lib\site-packages\tornado\gen.py", line 215, in wrapper
        result = func(*args, **kwargs)
      File "E:/soheil/web_site_root/ieee/all_functions/tornado-get.py", line 945, in get
        self.finish()
      File "C:\Python27\lib\site-packages\tornado\web.py", line 905, in finish
        raise RuntimeError("finish() called twice")
    RuntimeError: finish() called twice
[I 160530 19:45:32 web:1908] 304 GET /index (127.0.0.1) 20.00ms
[E 160530 19:45:32 web:1496] Uncaught exception GET /index (127.0.0.1)
    HTTPServerRequest(protocol='http', host='127.0.0.1:15001', method='GET', uri='/index', version='HTTP/1.1', remote_ip='127.0.0.1', headers={'Connection': 'keep-alive', 'Accept-Language': 'en-US,en;q=0.5', 'Accept-Encoding': 'gzip, deflate', 'If-None-Match': '"ac3838f960162e71ed9e305cb3d15695eead5282"', 'Host': '127.0.0.1:15001', 'Accept': 'text/html,application/xhtml+xml,application/xml;q=0.9,*/*;q=0.8', 'User-Agent': 'Mozilla/5.0 (Windows NT 6.1; WOW64; rv:46.0) Gecko/20100101 Firefox/46.0'})
    Traceback (most recent call last):
      File "C:\Python27\lib\site-packages\tornado\web.py", line 1369, in _stack_context_handle_exception
        raise_exc_info((type, value, traceback))
      File "C:\Python27\lib\site-packages\tornado\stack_context.py", line 314, in wrapped
        ret = fn(*args, **kwargs)
      File "C:\Python27\lib\site-packages\tornado\gen.py", line 149, in final_callback
        if future.result() is not None:
      File "C:\Python27\lib\site-packages\tornado\concurrent.py", line 215, in result
        raise_exc_info(self._exc_info)
      File "C:\Python27\lib\site-packages\tornado\gen.py", line 215, in wrapper
        result = func(*args, **kwargs)
      File "E:/soheil/web_site_root/ieee/all_functions/tornado-get.py", line 945, in get
        self.finish()
      File "C:\Python27\lib\site-packages\tornado\web.py", line 905, in finish
        raise RuntimeError("finish() called twice")
    RuntimeError: finish() called twice
[I 160530 19:45:46 web:1908] 200 GET /index (127.0.0.1) 9.00ms
[E 160530 19:45:46 web:1496] Uncaught exception GET /index (127.0.0.1)
    HTTPServerRequest(protocol='http', host='127.0.0.1:15001', method='GET', uri='/index', version='HTTP/1.1', remote_ip='127.0.0.1', headers={'Accept-Language': 'en-US,en;q=0.5', 'Accept-Encoding': 'gzip, deflate', 'Host': '127.0.0.1:15001', 'Accept': 'text/html,application/xhtml+xml,application/xml;q=0.9,*/*;q=0.8', 'User-Agent': 'Mozilla/5.0 (Windows NT 6.1; WOW64; rv:46.0) Gecko/20100101 Firefox/46.0', 'Connection': 'keep-alive', 'Pragma': 'no-cache', 'Cache-Control': 'no-cache'})
    Traceback (most recent call last):
      File "C:\Python27\lib\site-packages\tornado\web.py", line 1369, in _stack_context_handle_exception
        raise_exc_info((type, value, traceback))
      File "C:\Python27\lib\site-packages\tornado\stack_context.py", line 314, in wrapped
        ret = fn(*args, **kwargs)
      File "C:\Python27\lib\site-packages\tornado\gen.py", line 149, in final_callback
        if future.result() is not None:
      File "C:\Python27\lib\site-packages\tornado\concurrent.py", line 215, in result
        raise_exc_info(self._exc_info)
      File "C:\Python27\lib\site-packages\tornado\gen.py", line 215, in wrapper
        result = func(*args, **kwargs)
      File "E:/soheil/web_site_root/ieee/all_functions/tornado-get.py", line 945, in get
        self.finish()
      File "C:\Python27\lib\site-packages\tornado\web.py", line 905, in finish
        raise RuntimeError("finish() called twice")
    RuntimeError: finish() called twice
[E 160530 19:46:58 web:1496] Uncaught exception POST /index (127.0.0.1)
    HTTPServerRequest(protocol='http', host='127.0.0.1:15001', method='POST', uri='/index', version='HTTP/1.1', remote_ip='127.0.0.1', headers={'Content-Length': '200', 'Accept-Language': 'en-US,en;q=0.5', 'Accept-Encoding': 'gzip, deflate', 'Host': '127.0.0.1:15001', 'Accept': 'text/html,application/xhtml+xml,application/xml;q=0.9,*/*;q=0.8', 'User-Agent': 'Mozilla/5.0 (Windows NT 6.1; WOW64; rv:46.0) Gecko/20100101 Firefox/46.0', 'Connection': 'keep-alive', 'Referer': 'http://127.0.0.1:15001/index', 'Content-Type': 'application/x-www-form-urlencoded'})
    Traceback (most recent call last):
      File "C:\Python27\lib\site-packages\tornado\web.py", line 1369, in _stack_context_handle_exception
        raise_exc_info((type, value, traceback))
      File "C:\Python27\lib\site-packages\tornado\stack_context.py", line 314, in wrapped
        ret = fn(*args, **kwargs)
      File "C:\Python27\lib\site-packages\tornado\gen.py", line 149, in final_callback
        if future.result() is not None:
      File "C:\Python27\lib\site-packages\tornado\concurrent.py", line 215, in result
        raise_exc_info(self._exc_info)
      File "C:\Python27\lib\site-packages\tornado\gen.py", line 215, in wrapper
        result = func(*args, **kwargs)
      File "E:/soheil/web_site_root/ieee/all_functions/tornado-get.py", line 521, in post
        result = tornado.gen.Task(self.download(details))
      File "E:/soheil/web_site_root/ieee/all_functions/tornado-get.py", line 666, in download
        proxy=proxy,user_pass=user_pass,cookies=cookies,log_out=log_out,ftp_upload=ftp_upload,html=html)
      File "E:/soheil/web_site_root/ieee/all_functions\main_core.py", line 398, in download_link
        pdf_dw_dir, pdf_dw_Wr_dir = PDF_File(url,pdf_download_location,wat_locatton).finall_file_saving(html, file_name,pdf_download_location,no_watermarker=0)
      File "E:/soheil/web_site_root/ieee/all_functions\save_source.py", line 337, in finall_file_saving
        self.pdf_watermark_slow(localName.pdf_Folder_filename, localName.W_pdf_Folder_filename,url_wtm=url_watermark)
      File "E:/soheil/web_site_root/ieee/all_functions\save_source.py", line 221, in pdf_watermark_slow
        wt1 = self.watermark_file(self.Watermarked_PDF_Dir+"/" + "watermarker_slow_"+url_watermark+".pdf", url_watermark,center_text=True)
      File "E:/soheil/web_site_root/ieee/all_functions\save_source.py", line 130, in watermark_file
        pack = open(packet, 'a+')
    IOError: [Errno 22] invalid mode ('a+') or filename: 'E:/soheil/web_site_root/ieee/all_functions/static/watermarker_slow_http://free-papers.elasa.ir.pdf'
[E 160530 19:46:58 web:1908] 500 POST /index (127.0.0.1) 68135.00ms
[I 160530 19:50:06 web:1908] 200 GET /index (127.0.0.1) 19.00ms
[E 160530 19:50:06 web:1496] Uncaught exception GET /index (127.0.0.1)
    HTTPServerRequest(protocol='http', host='127.0.0.1:15001', method='GET', uri='/index', version='HTTP/1.1', remote_ip='127.0.0.1', headers={'Connection': 'keep-alive', 'Accept-Language': 'en-US,en;q=0.5', 'Accept-Encoding': 'gzip, deflate', 'Host': '127.0.0.1:15001', 'Accept': 'text/html,application/xhtml+xml,application/xml;q=0.9,*/*;q=0.8', 'User-Agent': 'Mozilla/5.0 (Windows NT 6.1; WOW64; rv:46.0) Gecko/20100101 Firefox/46.0'})
    Traceback (most recent call last):
      File "C:\Python27\lib\site-packages\tornado\web.py", line 1369, in _stack_context_handle_exception
        raise_exc_info((type, value, traceback))
      File "C:\Python27\lib\site-packages\tornado\stack_context.py", line 314, in wrapped
        ret = fn(*args, **kwargs)
      File "C:\Python27\lib\site-packages\tornado\gen.py", line 149, in final_callback
        if future.result() is not None:
      File "C:\Python27\lib\site-packages\tornado\concurrent.py", line 215, in result
        raise_exc_info(self._exc_info)
      File "C:\Python27\lib\site-packages\tornado\gen.py", line 215, in wrapper
        result = func(*args, **kwargs)
      File "E:/soheil/web_site_root/ieee/all_functions/tornado-get.py", line 945, in get
        self.finish()
      File "C:\Python27\lib\site-packages\tornado\web.py", line 905, in finish
        raise RuntimeError("finish() called twice")
    RuntimeError: finish() called twice
[E 160530 20:03:49 web:1496] Uncaught exception POST /index (127.0.0.1)
    HTTPServerRequest(protocol='http', host='127.0.0.1:15001', method='POST', uri='/index', version='HTTP/1.1', remote_ip='127.0.0.1', headers={'Content-Length': '200', 'Accept-Language': 'en-US,en;q=0.5', 'Accept-Encoding': 'gzip, deflate', 'Host': '127.0.0.1:15001', 'Accept': 'text/html,application/xhtml+xml,application/xml;q=0.9,*/*;q=0.8', 'User-Agent': 'Mozilla/5.0 (Windows NT 6.1; WOW64; rv:46.0) Gecko/20100101 Firefox/46.0', 'Connection': 'keep-alive', 'Referer': 'http://127.0.0.1:15001/index', 'Content-Type': 'application/x-www-form-urlencoded'})
    Traceback (most recent call last):
      File "C:\Python27\lib\site-packages\tornado\web.py", line 1369, in _stack_context_handle_exception
        raise_exc_info((type, value, traceback))
      File "C:\Python27\lib\site-packages\tornado\stack_context.py", line 314, in wrapped
        ret = fn(*args, **kwargs)
      File "C:\Python27\lib\site-packages\tornado\gen.py", line 149, in final_callback
        if future.result() is not None:
      File "C:\Python27\lib\site-packages\tornado\concurrent.py", line 215, in result
        raise_exc_info(self._exc_info)
      File "C:\Python27\lib\site-packages\tornado\gen.py", line 215, in wrapper
        result = func(*args, **kwargs)
      File "E:/soheil/web_site_root/ieee/all_functions/tornado-get.py", line 521, in post
        result = tornado.gen.Task(self.download(details))
      File "E:/soheil/web_site_root/ieee/all_functions/tornado-get.py", line 666, in download
        proxy=proxy,user_pass=user_pass,cookies=cookies,log_out=log_out,ftp_upload=ftp_upload,html=html)
      File "E:/soheil/web_site_root/ieee/all_functions\main_core.py", line 398, in download_link
        pdf_dw_dir, pdf_dw_Wr_dir = PDF_File(url,pdf_download_location,wat_locatton).finall_file_saving(html, file_name,pdf_download_location,no_watermarker=0)
      File "E:/soheil/web_site_root/ieee/all_functions\save_source.py", line 339, in finall_file_saving
        self.pdf_watermark_slow(localName.pdf_Folder_filename, localName.W_pdf_Folder_filename,url_wtm=url_watermark)
      File "E:/soheil/web_site_root/ieee/all_functions\save_source.py", line 223, in pdf_watermark_slow
        wt1 = self.watermark_file(self.Watermarked_PDF_Dir+"/" + "watermarker_slow_"+url_watermark+".pdf", url_watermark,center_text=True)
      File "E:/soheil/web_site_root/ieee/all_functions\save_source.py", line 130, in watermark_file
        pack = open(packet, 'a+')
    IOError: [Errno 22] invalid mode ('a+') or filename: 'E:/soheil/web_site_root/ieee/all_functions/static/watermarker_slow_http://free-papers.elasa.ir.pdf'
[E 160530 20:03:49 web:1908] 500 POST /index (127.0.0.1) 54904.00ms
[I 160530 20:06:46 web:1908] 200 GET /index (127.0.0.1) 21.00ms
[E 160530 20:06:46 web:1496] Uncaught exception GET /index (127.0.0.1)
    HTTPServerRequest(protocol='http', host='127.0.0.1:15001', method='GET', uri='/index', version='HTTP/1.1', remote_ip='127.0.0.1', headers={'Connection': 'keep-alive', 'Accept-Language': 'en-US,en;q=0.5', 'Accept-Encoding': 'gzip, deflate', 'Host': '127.0.0.1:15001', 'Accept': 'text/html,application/xhtml+xml,application/xml;q=0.9,*/*;q=0.8', 'User-Agent': 'Mozilla/5.0 (Windows NT 6.1; WOW64; rv:46.0) Gecko/20100101 Firefox/46.0'})
    Traceback (most recent call last):
      File "C:\Python27\lib\site-packages\tornado\web.py", line 1369, in _stack_context_handle_exception
        raise_exc_info((type, value, traceback))
      File "C:\Python27\lib\site-packages\tornado\stack_context.py", line 314, in wrapped
        ret = fn(*args, **kwargs)
      File "C:\Python27\lib\site-packages\tornado\gen.py", line 149, in final_callback
        if future.result() is not None:
      File "C:\Python27\lib\site-packages\tornado\concurrent.py", line 215, in result
        raise_exc_info(self._exc_info)
      File "C:\Python27\lib\site-packages\tornado\gen.py", line 215, in wrapper
        result = func(*args, **kwargs)
      File "E:/soheil/web_site_root/ieee/all_functions/tornado-get.py", line 945, in get
        self.finish()
      File "C:\Python27\lib\site-packages\tornado\web.py", line 905, in finish
        raise RuntimeError("finish() called twice")
    RuntimeError: finish() called twice
[I 160530 20:12:20 web:1908] 200 POST /index (127.0.0.1) 204770.00ms
[W 160530 20:12:20 web:1908] 404 GET /htmls/simple_cursor.css (127.0.0.1) 6.00ms
